Workbook

Sheet ACT 1
A1: 1 | B1: 2 | C1: 3 | D1: 4 | E1: 5 | F1: 6 | G1: 7 | H1: 8 | I1: 9 | J1: 10 | K1: 11 | L1: 12 | M1: 13 | N1: 14 | O1: 15 | P1: 16 | Q1: 17 | R1: 18 | S1: 19 | T1: 20
A2: CL | B2: α6 | C2: Δαi | D2: αD | E2: CD6 | F2: ΔCDi | G2: CDD | H2: cosαD | I2: sinαD | J2: CLcosαD | K2: CDDsinαD | L2: CN | M2: CLsinαD | N2: CDDcosαD | O2: CC | P2: C.P. | Q2: Cmc/4 | R2: Cma.c. | S2: CDi | T2: CD0
A3: 0 | B3: -1.96 | C3: 0 | D3: -1.96 | E3: 0.0084 | F3: 0 | G3: 0.0084 | H3: 0.99942 | I3: -0.0342 | J3: 0 | K3: -0.00029 | L3: 0 | M3: 0 | N3: 0.0084 | O3: 0.0084 | P3: - | Q3: - | R3: - | S3: 0 | T3: 0.0084
A4: 0.2 | B4: 0.99 | C4: -0.06 | D4: 0.93 | E4: 0.0113 | F4: -0.0002 | G4: 0.0111 | H4: 0.99987 | I4: 0.01631 | J4: 0.19997 | K4: 0.00018 | L4: 0.2 | M4: 0.00326 | N4: 0.0111 | O4: 0.0078 | P4: 43.02 | Q4: -0.03607 | R4: -0.03787 | S4: 0.0019 | T4: 0.0092
A5: 0.4 | B5: 3.79 | C5: -0.11 | D5: 3.68 | E5: 0.0192 | F5: -0.0008 | G5: 0.0184 | H5: 0.99794 | I5: 0.06416 | J5: 0.39918 | K5: 0.00118 | L5: 0.4 | M5: 0.02566 | N5: 0.01838 | O5: -0.0073 | P5: 33.65 | Q5: -0.03463 | R5: -0.03823 | S5: 0.0077 | T5: 0.0107
A6: 0.6 | B6: 6.38 | C6: -0.17 | D6: 6.21 | E6: 0.0307 | F6: -0.0018 | G6: 0.029 | H6: 0.99413 | I6: 0.10822 | J6: 0.59648 | K6: 0.00313 | L6: 0.6 | M6: 0.06493 | N6: 0.02878 | O6: -0.0362 | P6: 31.2 | Q6: -0.03718 | R6: -0.04257 | S6: 0.0174 | T6: 0.0116
A7: 0.8 | B7: 9.03 | C7: -0.22 | D7: 8.81 | E7: 0.0471 | F7: -0.0031 | G7: 0.044 | H7: 0.98821 | I7: 0.15311 | J7: 0.79057 | K7: 0.00674 | L7: 0.797 | M7: 0.12249 | N7: 0.04347 | O7: -0.079 | P7: 30.12 | Q7: -0.04082 | R7: -0.048 | S7: 0.0309 | T7: 0.0131
A8: 1 | B8: 12.03 | C8: -0.28 | D8: 11.75 | E8: 0.071 | F8: -0.0049 | G8: 0.0661 | H8: 0.97904 | I8: 0.20366 | J8: 0.97904 | K8: 0.01347 | L8: 0.993 | M8: 0.20366 | N8: 0.06475 | O8: -0.1389 | P8: 29.26 | Q8: -0.04228 | R8: -0.05121 | S8: 0.0483 | T8: 0.0178
A9: 1.2 | B9: 14.77 | C9: -0.33 | D9: 14.44 | E9: 0.0996 | F9: -0.007 | G9: 0.0926 | H9: 0.96843 | I9: 0.24929 | J9: 1.16212 | K9: 0.02308 | L9: 1.185 | M9: 0.29915 | N9: 0.08968 | O9: -0.2095 | P9: 27.05 | Q9: -0.0243 | R9: -0.03496 | S9: 0.0696 | T9: 0.023
A10: 1.4 | B10: 18.07 | C10: -0.39 | D10: 17.68 | E10: 0.1372 | F10: -0.0095 | G10: 0.1277 | H10: 0.95277 | I10: 0.3037 | J10: 1.33388 | K10: 0.03877 | L10: 1.373 | M10: 0.42517 | N10: 0.12164 | O10: -0.3035 | P10: 26.58 | Q10: -0.02169 | R10: -0.03404 | S10: 0.0947 | T10: 0.033
A11: 1.54 | B11: 21.9 | C11: -0.43 | D11: 21.47 | E11: 0.1898 | F11: -0.0115 | G11: 0.1783 | H11: 0.93061 | I11: 0.36603 | J11: 1.43313 | K11: 0.06525 | L11: 1.498 | M11: 0.56368 | N11: 0.1659 | O11: -0.3978 | P11: 26.61 | Q11: -0.02412 | R11: -0.03761 | S11: 0.1146 | T11: 0.0637
A40: =HLOOKUP($E$3,$C$35:$AP$97,2,FALSE) -> #N/A | B40: =#REF!-A40 -> #REF!
A41: =HLOOKUP($E$3,$C$35:$AP$97,3,FALSE) -> #N/A | B41: =#REF!-A41 -> #REF!
A42: =HLOOKUP($E$3,$C$35:$AP$97,4,FALSE) -> #N/A | B42: =#REF!-A42 -> #REF!
A43: =HLOOKUP($E$3,$C$35:$AP$97,5,FALSE) -> #N/A | B43: =#REF!-A43 -> #REF!
A44: =HLOOKUP($E$3,$C$35:$AP$97,6,FALSE) -> #N/A | B44: =#REF!-A44 -> #REF!
A45: =HLOOKUP($E$3,$C$35:$AP$97,7,FALSE) -> #N/A | B45: =#REF!-A45 -> #REF!
A46: =HLOOKUP($E$3,$C$35:$AP$97,8,FALSE) -> #N/A | B46: =#REF!-A46 -> #REF!
A47: =HLOOKUP($E$3,$C$35:$AP$97,9,FALSE) -> #N/A | B47: =#REF!-A47 -> #REF!
A48: =HLOOKUP($E$3,$C$35:$AP$97,10,FALSE) -> #N/A | B48: =#REF!-A48 -> #REF!

Sheet ACT 2
B4: GIVEN | E4: CALCULATIONS | I4: TABLE 1
I5: ① | J5: ② | K5: ③ | L5: ④ | M5: ⑤
I6: V | J6: V | K6: V^2 | L6: +n | M6: -n
B7: DATA | C7: VALUES | E7: n | F7: =2.1+(24000/(C8+10000)) -> 4.1602181 | I7: mph | J7: fps | K7: fps^2 | L7: - | M7: -
B8: W (act 3-1) | C8: 1649.2521 | E8: -n | F8: =C23*F7 -> -1.6640872 | I8: 0 | J8: =I8*22/15 -> 0 | K8: =J8^2 -> 0 | L8: =$F$12*K8 -> 0 | M8: =$F$13*K8 -> 0
B9: S (act 3-1) | C9: 126.521 | E9: VA (mph) | F9: =C11*SQRT(F7) -> 117.36231 | I9: 10 | J9: =I9*22/15 -> 14.666667 | K9: =J9^2 -> 215.11111 | L9: =$F$12*K9 -> 0.030203605 | M9: =$F$13*K9 -> -0.012081442
B10: W/S (act 3-1) | C10: =C8/C9 -> 13.035402 | E10: CNA | F10: =(F7*C8)/(0.5*0.002377*((F9*22/15)^2)*C9) -> 1.5400016 | I10: 20 | J10: =I10*22/15 -> 29.333333 | K10: =J10^2 -> 860.44444 | L10: =$F$12*K10 -> 0.12081442 | M10: =$F$13*K10 -> -0.048325767
B11: Vs (mph) (act 10-1) | C11: 57.5401 | E11: -CNA | F11: =(F8*C8)/(0.5*0.002377*(F9*22/15)^2*C9) -> -0.61600065 | I11: 30 | J11: =I11*22/15 -> 44 | K11: =J11^2 -> 1936 | L11: =$F$12*K11 -> 0.27183244 | M11: =$F$13*K11 -> -0.10873298
B12: Vmax (mph)(act 12-1) | C12: 139.64 | E12: n(CNA) | F12: =(F10*0.5*0.002377)/(C10) -> 0.00014040932 | I12: 40 | J12: =I12*22/15 -> 58.666667 | K12: =J12^2 -> 3441.7778 | L12: =$F$12*K12 -> 0.48325767 | M12: =$F$13*K12 -> -0.19330307
B13: CLmax (act 1-2) | C13: 1.54 | E13: n(-CNA) | F13: =(F11*0.5*0.002377)/(C10) -> -5.6163727e-05 | I13: 50 | J13: =I13*22/15 -> 73.333333 | K13: =J13^2 -> 5377.7778 | L13: =$F$12*K13 -> 0.75509011 | M13: =$F$13*K13 -> -0.30203605
B14: αD at CL=0.6 (act 1-2) | C14: 6.2127 | E14: Vc(des) | F14: =0.9*C12 -> 125.676 | I14: 60 | J14: =I14*22/15 -> 88 | K14: =J14^2 -> 7744 | L14: =$F$12*K14 -> 1.0873298 | M14: =$F$13*K14 -> -0.43493191
B15: αD at CL=0 (act 1-2) | C15: -1.96 | E15: Vc(min) | F15: =C24*SQRT(C10) -> 137.19738 | I15: 70 | J15: =I15*22/15 -> 102.66667 | K15: =J15^2 -> 10540.444 | L15: =$F$12*K15 -> 1.4799766 | M15: =$F$13*K15 -> -0.59199065
B16: U Vc (set by prof) | C16: 30 | I16: 80 | J16: =I16*22/15 -> 117.33333 | K16: =J16^2 -> 13767.111 | L16: =$F$12*K16 -> 1.9330307 | M16: =$F$13*K16 -> -0.77321228
B17: U Vd (set by prof) | C17: 15 | E17: Vc to use: | F17: =IF(F14>F15, F14, F15) -> 137.19738 | I17: 90 | J17: =I17*22/15 -> 132 | K17: =J17^2 -> 17424 | L17: =$F$12*K17 -> 2.446492 | M17: =$F$13*K17 -> -0.97859679
E18: K | F18: =0.5*((C10^(1/4))) -> 0.95006017 | I18: 100 | J18: =I18*22/15 -> 146.66667 | K18: =J18^2 -> 21511.111 | L18: =$F$12*K18 -> 3.0203605 | M18: =$F$13*K18 -> -1.2081442
B19: What is your aircraft type? | E19: a (rad) | F19: =(0.6)/(C14-C15)*(180/PI()) -> 4.2063783 | I19: 110 | J19: =I19*22/15 -> 161.33333 | K19: =J19^2 -> 26028.444 | L19: =$F$12*K19 -> 3.6546361 | M19: =$F$13*K19 -> -1.4618545
B20: Normal, Utility, or Acrobatic: | C20: Utility | E20: (limit gust load) n = | F20: 1 ± V* | G20: =(F18*C16*F19)/(575*C10) -> 0.015995154 | I20: 117.36231 | J20: =I20*22/15 -> 172.13139 | K20: =J20^2 -> 29629.216 | L20: =$F$12*K20 -> 4.1602181 | M20: =$F$13*K20 -> -1.6640872
E21: n = | F21: =1+G20*F17 -> 3.1944931 | G21: =1-G20*F17 -> -1.1944931 | I21: 0 | J21: =I21*22/15 -> 0 | K21: =J21^2 -> 0 | L21: =$F$12*K21 -> 0 | M21: =$F$13*K21 -> 0
B22: CONSTANT FACTORS
B23: -n | C23: =IF(C20="acrobatic", "-0.5", "-0.4") -> -0.4 | E23: Vd (mph) | F23: =C25*F15 -> 205.79607
B24: Vc(min) (mph) | C24: =IF(C20="acrobatic", "41", "38") -> 38 | E24: (limit gust load) n = | F24: 1 ± V* | G24: =(F18*C17*F19)/(575*C10) -> 0.0079975768 | I24: TABLE 2 | M24: TABLE 3
B25: Vd (mph) | C25: =IF(C20="acrobatic", "1.55", IF(C20="utility", "1.5", "1.4")) -> 1.5 | E25: n = | F25: =1+G24*F23 -> 2.6458699 | G25: =1-G24*F23 -> -0.64586986 | I25: ① | J25: ② | K25: ③ | M25: ① | N25: ② | O25: ③
I26: V | J26: +n | K26: -n | M26: V | N26: +n | O26: -n
E27: Clmaxδf | F27: =$C$13+0.5 -> 2.04 | I27: mph | J27: - | K27: - | M27: mph | N27: - | O27: -
E28: VSL (fps) | F28: =SQRT(C10*(2/0.002377)*(1/F27)) -> 73.324235 | I28: 0 | J28: =1+$G$20*I28 -> 1 | K28: =1-$G$20*I28 -> 1 | M28: 0 | N28: =1+$G$24*M28 -> 1 | O28: =1-$G$24*M28 -> 1
E29: VF (mph) | F29: =1.4*C11 -> 80.55614 | G29: =1.8*(F28*(15/22)) -> 89.988833 | I29: 10 | J29: =1+$G$20*I29 -> 1.1599515 | K29: =1-$G$20*I29 -> 0.84004846 | M29: 10 | N29: =1+$G$24*M29 -> 1.0799758 | O29: =1-$G$24*M29 -> 0.92002423
E30: VF to use: | F30: =IF(F29>G29, F29, G29) -> 89.988833 | I30: 20 | J30: =1+$G$20*I30 -> 1.3199031 | K30: =1-$G$20*I30 -> 0.68009693 | M30: 20 | N30: =1+$G$24*M30 -> 1.1599515 | O30: =1-$G$24*M30 -> 0.84004846
I31: 30 | J31: =1+$G$20*I31 -> 1.4798546 | K31: =1-$G$20*I31 -> 0.52014539 | M31: 30 | N31: =1+$G$24*M31 -> 1.2399273 | O31: =1-$G$24*M31 -> 0.76007269
I32: 40 | J32: =1+$G$20*I32 -> 1.6398061 | K32: =1-$G$20*I32 -> 0.36019385 | M32: 40 | N32: =1+$G$24*M32 -> 1.3199031 | O32: =1-$G$24*M32 -> 0.68009693
I33: 50 | J33: =1+$G$20*I33 -> 1.7997577 | K33: =1-$G$20*I33 -> 0.20024232 | M33: 50 | N33: =1+$G$24*M33 -> 1.3998788 | O33: =1-$G$24*M33 -> 0.60012116
I34: 60 | J34: =1+$G$20*I34 -> 1.9597092 | K34: =1-$G$20*I34 -> 0.040290778 | M34: 60 | N34: =1+$G$24*M34 -> 1.4798546 | O34: =1-$G$24*M34 -> 0.52014539
I35: 70 | J35: =1+$G$20*I35 -> 2.1196608 | K35: =1-$G$20*I35 -> -0.11966076 | M35: 70 | N35: =1+$G$24*M35 -> 1.5598304 | O35: =1-$G$24*M35 -> 0.44016962
I36: 80 | J36: =1+$G$20*I36 -> 2.2796123 | K36: =1-$G$20*I36 -> -0.2796123 | M36: 80 | N36: =1+$G$24*M36 -> 1.6398061 | O36: =1-$G$24*M36 -> 0.36019385
I37: 90 | J37: =1+$G$20*I37 -> 2.4395638 | K37: =1-$G$20*I37 -> -0.43956383 | M37: 90 | N37: =1+$G$24*M37 -> 1.7197819 | O37: =1-$G$24*M37 -> 0.28021808
I38: 100 | J38: =1+$G$20*I38 -> 2.5995154 | K38: =1-$G$20*I38 -> -0.59951537 | M38: 100 | N38: =1+$G$24*M38 -> 1.7997577 | O38: =1-$G$24*M38 -> 0.20024232
I39: 110 | J39: =1+$G$20*I39 -> 2.7594669 | K39: =1-$G$20*I39 -> -0.75946691 | M39: 110 | N39: =1+$G$24*M39 -> 1.8797335 | O39: =1-$G$24*M39 -> 0.12026655
I40: 120 | J40: =1+$G$20*I40 -> 2.9194184 | K40: =1-$G$20*I40 -> -0.91941844 | M40: 120 | N40: =1+$G$24*M40 -> 1.9597092 | O40: =1-$G$24*M40 -> 0.040290778
I41: 117.36231 | J41: =1+$G$20*I41 -> 2.8772282 | K41: =1-$G$20*I41 -> -0.87722824 | M41: 130 | N41: =1+$G$24*M41 -> 2.039685 | O41: =1-$G$24*M41 -> -0.03968499
I42: 0 | J42: =1+$G$20*I42 -> 1 | K42: =1-$G$20*I42 -> 1 | M42: 140 | N42: =1+$G$24*M42 -> 2.1196608 | O42: =1-$G$24*M42 -> -0.11966076
M43: 150 | N43: =1+$G$24*M43 -> 2.1996365 | O43: =1-$G$24*M43 -> -0.19963653
...

Sheet ACT 3
C3: Constants | F3: Taken from | I3: Condition 1: | L3: U | M3: 30 | N3: fps | Q3: Condition 3: | T3: U | U3: 15 | V3: fps | X3: Condition 6: | AE3: Condition 9:
I4: Δn1a | J4: =(D18*M3*D12*D19)/(575*D7) -> 2.20908 | Q4: Kg | R4: =0.08+(1850/(D5+3000)) -> 0.47791346 | X4: CC VI | Y4: =(MAX('ACT 1'!O3:O11))+0.06 -> 0.0684 | AA4: Extrapolation | AE4: CL IX | AF4: =(D5)/(0.5*D20*(D17^2)*D6) -> 0.62962678
C5: W | D5: ='[1]ACT 3'!$M$7 -> 1649.2521 | E5: lb | F5: ACT 3, AIRDESGN1 | I5: Δn1b | J5: =(0.77+(32000/(D5+9200)))*(3.25/(D8^0.435)) -> 3.9355489 | L5: Interpolation | Q5: Vm | R5: =(29*(D5/D11)^0.5)*(15/22) -> 364.61832 | S5: mph | X5: CN VI | Y5: =AC7 -> -0.60264901 | AB5: CC VI | AC5: CN VI | AE5: CC IX | AF5: =AJ8 -> -0.042540131 | AH5: Interpolation
C6: S | D6: ='[1]ACT 3'!$R$14 -> 126.521 | E6: ft^2 | F6: ACT 3, AIRDESGN1 | I6: Highest | J6: =MAX(J4:J5) -> 3.9355489 | M6: CN | N6: CC | Q6: Vg (1st) | R6: =D12+((R4)*(R5-D12)) -> 246.36103 | S6: mph | T6: Interpolation | X6: n VI | Y6: =(Y5*R22)/D7 -> -5.3803102 | AA6: Low | AB6: 0.0078 | AC6: 0.2 | AE6: CN IX | AF6: =AJ12 -> 0.62918238 | AI6: CL IX | AJ6: CC IX
C7: W/S | D7: ='[1]ACT 3'!$L$45 -> 13.035402 | E7: lb/ft^2 | F7: ACT 3, AIRDESGN1 | L7: Low | M7: 1.185 | N7: -0.2095 | Q7: Vg (2nd) | R7: =D12+100 -> 238.10934 | S7: mph | U7: CNIII | V7: CpIII | X7: C.P. VI | Y7: =AJ28 -> 80.624106 | Z7: % | AA7: Mid | AB7: 0.0684 | AC7: =((AB7-AB6)/(AB8-AB6))*(AC8-AC6)+(AC6) -> -0.60264901 | AE7: nIX | AF7: =(AF6*Y17)/D7 -> 0.99929418 | AH7: Low | AI7: 0.6 | AJ7: -0.0362
C8: W/P | D8: ='[1]ACT 3'!$L$42 -> 13.194017 | E8: lb/hp | F8: ACT 3, AIRDESGN1 | I8: nI | J8: =1+J6 -> 4.9355489 | L8: Mid | M8: =J10 -> 1.319319 | N8: =((M8-M7)/(M9-M7))*(N9-N7)+(N7) -> -0.27665951 | Q8: Vg (3rd) | R8: =1.5*D12 -> 207.164 | S8: mph | T8: Low | U8: 0.2 | V8: 43.02 | X8: Cm VI | Y8: =AJ32 -> -0.036785232 | AA8: Upper | AB8: -0.0073 | AC8: 0.4 | AE8: C.P. IX | AF8: =AJ16 -> 31.040015 | AH8: Mid | AI8: =AF4 -> 0.62962678 | AJ8: =((AI8-AI7)/(AI9-AI7))*(AJ9-AJ7)+(AJ7) -> -0.042540131
C9: MAC | D9: ='[1]ACT 3'!$R$16 -> 4.3849875 | E9: ft | F9: ACT 3, AIRDESGN1 | I9: qLI | J9: =(1/2)*(D20)*(D13)^2 -> 48.765208 | K9: lb/ft^2 | L9: Upper | M9: 1.373 | N9: -0.3035 | Q9: ΔnIIIa | R9: =(D18*U3*(MAX(R6:R8))*D19)/(575*D7) -> 1.9702912 | T9: Mid | U9: =R12 -> 0.41462344 | V9: =((U9-U8)/(U10-U8))*(V10-V8)+(V8) -> 32.964892 | X9: N VI | Y9: =Y5*R11*D6 -> -11831.318 | Z9: lb | AB9: =Y5 -> -0.60264901 | AE9: Cm IX | AF9: =AJ20 -> -0.043374367 | AH9: Upper | AI9: 0.8 | AJ9: -0.079
C10: SD | D10: ='[1]ACT 9'!$S$27 -> 0.45058173 | E10: m^2 | F10: ACT 9, AIRDESGN1 | I10: CNI | J10: =(J8*D7)/J9 -> 1.319319 | Q10: nIII | R10: =MAX(R9,J5)+1 -> 4.9355489 | T10: Upper | U10: 0.4 | V10: 33.65 | X10: C VI | Y10: =Y4*R11*D6 -> 1342.8415 | Z10: lb | AB10: 0 | AE10: N IX | AF10: =AF6*Y17*D6 -> 1648.0881 | AG10: lb | AI10: CC IX | AJ10: CN IX
D11: =D10*10.7639 -> 4.8500167 | E11: ft^2 | I11: CCI | J11: =-0.02*J10 -> -0.02638638 | Q11: qg | R11: =(0.5)*(D20)*(MAX(R6:R8)*(22/15))^2 -> 155.16939 | S11: lb/ft^2 | U11: CNIII | V11: CmIII | X11: MP VI | Y11: =Y8*Y17*D6*D9 -> -422.51849 | Z11: ft-lb | AB11: 0.2 | AE11: C IX | AF11: =AF5*Y17*D6 -> -111.43014 | AH11: Low | AI11: =AJ7 -> -0.0362 | AJ11: 0.6
C12: VMAX or VL | D12: ='[1]ACT 11'!$P$34 -> 138.10934 | E12: mph | F12: ACT 11, AIRDESGN1 | I12: interpolated CCI | J12: =MIN(N8,J11) -> -0.27665951 | K12: higher neg | Q12: CNIII | R12: =(R10*D7)/(R11) -> 0.41462344 | T12: Low | U12: 0.2 | V12: -0.03787 | AE12: MP IX | AF12: =AF9*Y17*D6*D9 -> -498.2019 | AG12: ft-lb | AH12: Mid | AI12: =AJ8 -> -0.042540131 | AJ12: =((AI12-AI11)/(AI13-AI11))*(AJ13-AJ11)+(AJ11) -> 0.62918238
D13: =D12*1.46667 -> 202.56082 | E13: fps | I13: C.P.I | J13: ='ACT 1'!P11 -> 26.61 | K13: % | Q13: CC III | R13: 0 | T13: Mid | U13: 0.331 | V13: =((U13-U12)/(U14-U12))*(V14-V12)+(V12) -> -0.0381058 | X13: Condition 7: | AA13: U | AB13: 15 | AC13: fps | AH13: Upper | AI13: =AJ9 -> -0.079 | AJ13: 0.797
C14: CL MAX | D14: 1.53 | F14: ACT 1, AIRDESGN2 | I14: CmI | J14: =(D15-(J13/100))*(J10) -> -0.033114907 | Q14: C.P. III | R14: =V9 -> 32.964892 | S14: % | T14: Upper | U14: 0.4 | V14: -0.03823 | X14: ΔnVII | Y14: =(D18*AB13*D16*D19)/(575*D7) -> 0.71969259 | AI14: CN IX | AJ14: C.P. IX
C15: a.c. | D15: 0.241 | F15: ACT1, AIRDESGN2 | I15: NI | J15: =(J10*J9*D6) -> 8139.9647 | K15: lb | Q15: Cm III | R15: =V13 -> -0.0381058 | X15: nVII | Y15: =1+Y14 -> 1.7196926 | Z15: conditions are not met nVII < 2 | AH15: Low | AI15: 0.6 | AJ15: 31.2
C16: VF | D16: ='ACT 2 v2'!AQ9 -> 89.988833 | E16: mph | F16: ACT 2, AIRDESGN2 | I16: CI | J16: =(J12*J9*D6) -> -1706.9402 | K16: lb | Q16: N III | R16: =R12*R11*D6 -> 8139.9647 | S16: lb | X16: *use | Y16: 2 | AH16: Mid | AI16: =AJ12 -> 0.62918238 | AJ16: =((AI16-AI15)/(AI17-AI15))*(AJ17-AJ15)+(AJ15) -> 31.040015
D17: =D16*1.46667 -> 131.98392 | E17: fps | I17: MPI | J17: =(J14*J9*D6*D9) -> -895.91045 | K17: ft-lb | Q17: CIII | R17: =R13*D6 -> 0 | X17: qF | Y17: =(1/2)*D20*D17^2 -> 20.70338 | AH17: Upper | AI17: 0.797 | AJ17: 30.12
C18: K | D18: ='ACT 2 v2'!Q9 -> 0.95006017 | F18: ACT 2, AIRDESGN2 | Q18: MPIII | R18: =V13*R11*D6*D9 -> -3280.4099 | S18: ft-lb | X18: CN VII | Y18: =(2*D7)/Y17 -> 1.2592536 | AA18: Interpolation | AI18: CN IX | AJ18: Cm IX
C19: a | D19: ='ACT 2 v2'!Q22 -> 4.2063783 | E19: /rad | F19: ACT 2, AIRDESGN2 | X19: CC VII | Y19: =AC21 -> -0.24662678 | AB19: CN VII | AC19: CC VII | AH19: Low | AI19: 0.6 | AJ19: -0.04257
C20: p | D20: 0.002377 | E20: slug/ft^3 | F20: ACT 2, AIRDESGN2 | I20: Condition 1': | L20: Interpolation | Q20: Condition 3': | X20: C.P. VII | Y20: =AC25 -> 26.864366 | Z20: % | AA20: Low | AB20: 1.185 | AC20: -0.2095 | AH20: Mid | AI20: =AI16 -> 0.62918238 | AJ20: =((AI20-AI19)/(AI21-AI19))*(AJ21-AJ19)+(AJ19) -> -0.043374367
I21: nI' | J21: =J8 -> 4.9355489 | M21: CN | N21: Cp | Q21: nIII' | R21: =R10 -> 4.9355489 | X21: Cm VII | Y21: =AC29 -> -0.034596631 | AA21: Mid | AB21: 1.2592536 | AC21: =((AB21-AB20)/(AB22-AB20))*(AC22-AC20)+(AC20) -> -0.24662678 | AH21: Upper | AI21: 0.797 | AJ21: -0.048
A22: CONDITION | B22: I | C22: I’ | D22: II | E22: III | F22: III’ | I22: CN' | J22: =J10 -> 1.319319 | L22: Low | M22: 1.2 | N22: 27.05 | Q22: q'g | R22: =0.75*R11 -> 116.37704 | S22: lb/ft^2 | X22: N VII | Y22: =Y18*Y17*D6 -> 3298.5043 | Z22: lb | AA22: Upper | AB22: 1.373 | AC22: -0.3035
A23: V (mph) | B23: =$D$12 -> 138.10934 | C23: =$D$12 -> 138.10934 | D23: =$D$12 -> 138.10934 | E23: =MAX(R6:R8) -> 246.36103 | F23: =R24 -> 213.35491 | I23: CCI' | J23: =MAX(J12,J11) -> -0.02638638 | L23: Mid | M23: 1.319319 | N23: =((M23-M22)/(M24-M22))*(N24-N22)+(N22) -> 26.7696 | Q23: CNIII' | R23: =(R21*D7)/R22 -> 0.55283126 | T23: Interpolation | X23: C VII | Y23: =Y19*Y17*D6 -> -646.01723 | Z23: lb | AB23: CN VII | AC23: C.P. VII
A24: q (lb/ft^2) | B24: =J9 -> 48.765208 | C24: =B24 -> 48.765208 | D24: 43.63 | E24: =R11 -> 155.16939 | F24: =R22 -> 116.37704 | I24: C.P. I' | J24: =MAX(N23:N24) -> 26.7696 | K24: % | L24: Upper | M24: 1.4 | N24: 26.58 | Q24: V'g | R24: =(((2*R22)/D20)^0.5)*(15/22) -> 213.35491 | S24: mph | U24: CNIII | V24: CpIII | X24: MP VII | Y24: =Y21*Y17*D6*D9 -> -397.38003 | Z24: ft-lb | AA24: Low | AB24: 1.185 | AC24: 27.05
A25: U (ft/s) | B25: =M3 -> 30 | C25: =B25 -> 30 | D25: -30 | E25: =U3 -> 15 | F25: 15 | I25: CmI' | J25: =(D15-(N23/100))*(J22) -> -0.035220545 | Q25: CC III' | R25: 0 | T25: Low | U25: 0.4 | V25: 33.65 | AA25: Mid | AB25: 1.2592536 | AC25: =((AB25-AB24)/(AB26-AB24))*(AC26-AC24)+(AC24) -> 26.864366
A26: Δn (gust) | B26: =J4 -> 2.20908 | C26: =B26 -> 2.20908 | D26: =J31 -> -2.20908 | E26: =R9 -> 1.9702912 | F26: =E26 -> 1.9702912 | I26: NI' | J26: =J22*J9*D6 -> 8139.9647 | K26: lb | Q26: C.P. III' | R26: =V26 -> 31.777817 | S26: % | T26: Mid | U26: =R23 -> 0.55283126 | V26: =((U26-U25)/(U27-U25))*(V27-V25)+(V25) -> 31.777817 | AA26: Upper | AB26: 1.373 | AC26: 26.58 | AE26: Condition 6: Extra
A27: Δn (maneuver) | B27: =J5 -> 3.9355489 | C27: =B27 -> 3.9355489 | D27: - | E27: =B27 -> 3.9355489 | F27: =E27 -> 3.9355489 | I27: CI' | J27: =J23*J9*D6 -> -162.79929 | K27: lb | Q27: Cm III' | R27: =(0.75*R15)+(0.08-R15) -> 0.08952645 | T27: Upper | U27: 0.6 | V27: 31.2 | AB27: CN VII | AC27: Cm VII | AE27: Extrapolation | AH27: Extrapolation
A28: n | B28: =J8 -> 4.9355489 | C28: =B28 -> 4.9355489 | D28: =J32 -> -1.20908 | E28: =R10 -> 4.9355489 | F28: =E28 -> 4.9355489 | I28: MPI' | J28: =J25*J9*D6*D9 -> -952.87762 | K28: ft-lb | Q28: N III' | R28: =R23*R22*D6 -> 8139.9647 | S28: lb | AA28: Low | AB28: 1.185 | AC28: -0.03496 | AE28: Low | AF28: 0 | AG28: =AC42 -> 52.39 | AI28: =AC7 -> -0.60264901 | AJ28: =FORECAST(AI28,AJ29:AJ30,AI29:AI30) -> 80.624106
A29: CN | B29: =J10 -> 1.319319 | C29: =J22 -> 1.319319 | D29: =J33 -> -0.32319855 | E29: =R12 -> 0.41462344 | F29: =R23 -> 0.55283126 | Q29: CIII' | R29: =R25*R22*D6 -> 0 | S29: lb | AA29: Mid | AB29: 1.2592536 | AC29: =((AB29-AB28)/(AB30-AB28))*(AC30-AC28)+(AC28) -> -0.034596631 | AE29: Mid | AF29: 0.2 | AG29: =AC43 -> 43.02 | AI29: 0 | AJ29: 52.39
A30: CC | B30: =J12 -> -0.27665951 | C30: =J23 -> -0.02638638 | D30: 0 | E30: =R13 -> 0 | F30: =R25 -> 0 | I30: Condition 2: | L30: U | M30: -30 | N30: FPS | Q30: MPIII' | R30: =R27*R22*D6*D9 -> 5780.2904 | S30: ft-lb | AA30: Upper | AB30: 1.373 | AC30: -0.03404 | AE30: Upper | AF30: 0.4 | AG30: =AC44 -> 33.65 | AI30: 0.2 | AJ30: 43.02
A31: C.P. (%) | B31: =J13 -> 26.61 | C31: =J24 -> 26.7696 | D31: =J35 -> 67.531852 | E31: =R14 -> 32.964892 | F31: =R26 -> 31.777817 | I31: ΔnIIa | J31: =(D18*M30*D12*D19)/(575*D7) -> -2.20908
A32: Cm | B32: =J14 -> -0.033114907 | C32: =J25 -> -0.035220545 | D32: =J36 -> -0.03983703 | E32: =R15 -> -0.0381058 | F32: =R27 -> 0.08952645 | I32: nII | J32: =1+J31 -> -1.20908 | L32: Extrapolation | Q32: Condition 4: | T32: U | U32: -15 | V32: fps | X32: Condition 8: | AA32: U | AB32: -15 | AC32: fps | AF32: 0 | AG32: =FORECAST(AF32,AG33:AG34,AF33:AF34) -> -0.03751 | AI32: -0.60264901 | AJ32: =FORECAST(AI32,AJ33:AJ34,AI33:AI34) -> -0.036785232
A33: N (lb) | B33: =J15 -> 8139.9647 | C33: =J26 -> 8139.9647 | D33: =J37 -> -1994.0778 | E33: =R16 -> 8139.9647 | F33: =R28 -> 8139.9647 | I33: CNII | J33: =((J32*D7)/(J9)) -> -0.32319855 | M33: CL | N33: Cp | Q33: ΔnIV | R33: =(D18*U32*(MAX(R6:R8))*D19)/(575*D7) -> -1.9702912 | X33: ΔnVIII | Y33: =(D18*AB32*D16*D19)/(575*D7) -> -0.71969259 | AF33: 0.2 | AG33: -0.03787 | AI33: 0 | AJ33: -0.03787
A34: C (lb) | B34: =J16 -> -1706.9402 | C34: =J27 -> -162.79929 | D34: =J38 -> 0 | E34: =R17 -> 0 | F34: =R29 -> 0 | I34: CCII | J34: 0 | L34: Low | M34: 0 | N34: =FORECAST(M34,N35:N36,M35:M36) -> 52.39 | Q34: nIV | R34: =1+R33 -> -0.97029122 | X34: nVIII | Y34: =1+Y33 -> 0.28030741 | AF34: 0.4 | AG34: -0.03823 | AI34: 0.2 | AJ34: -0.03823
A35: MP (ft-lb) | B35: =J17 -> -895.91045 | C35: =J28 -> -952.87762 | D35: =J39 -> -1077.7748 | E35: =R18 -> -3280.4099 | F35: =R30 -> 5780.2904 | I35: C.P.II | J35: =N38 -> 67.531852 | K35: % | L35: Mid | M35: 0.2 | N35: 43.02 | Q35: CNIV | R35: =(R34*D7)/R22 -> -0.1086824 | T35: Interpolation | X35: CN VIII | Y35: =(Y34*D7)/Y17 -> 0.17648905 | AA35: Interpolation
I36: CmII | J36: =N46 -> -0.03983703 | L36: Upper | M36: 0.4 | N36: 33.65 | Q36: CC IV | R36: 0 | U36: CNIIV | V36: CpIV | X36: CC VIII | Y36: =AC38 -> 0.0078705329 | AB36: CN VIII | AC36: CC VIII
A37: CONDITION | B37: IV | C37: V | D37: VI | E37: VII | F37: VIII | G37: IX | I37: NII | J37: =J33*J9*D6 -> -1994.0778 | K37: lb | M37: CNII | N37: CPII | Q37: C.P. IV | R37: =V38 -> 29.693842 | S37: % | T37: Low | U37: -0.079 | V37: 30.12 | X37: C.P. VIII | Y37: =AC48 -> 44.121488 | Z37: % | AA37: Low | AB37: 0 | AC37: 0.0084
A38: V (mph) | B38: =E23 -> 246.36103 | C38: =B23 -> 138.10934 | D38: =B38 -> 246.36103 | E38: =D16 -> 89.988833 | F38: =D16 -> 89.988833 | G38: =D16 -> 89.988833 | I38: CII | J38: =J34*J9*D6 -> 0 | K38: lb | L38: Low | M38: =J33 -> -0.32319855 | N38: =FORECAST(M38,N39:N40,M39:M40) -> 67.531852 | Q38: Cm IV | R38: =V42 -> -0.039835647 | T38: Mid | U38: =R35 -> -0.1086824 | V38: =((U38-U37)/(U39-U37))*(V39-V37)+(V37) -> 29.693842 | X38: Cm VIII | Y38: =AC58 -> -0.03782768 | AA38: Mid | AB38: 0.17648905 | AC38: =((AB38-AB37)/(AB39-AB37))*(AC39-AC37)+(AC37) -> 0.0078705329
A39: q (lb/ft^2) | B39: =R22 -> 116.37704 | C39: =J9 -> 48.765208 | D39: =B39 -> 116.37704 | E39: =Y17 -> 20.70338 | F39: =Y17 -> 20.70338 | G39: =Y17 -> 20.70338 | I39: MPII | J39: =J36*J9*D6*D9 -> -1077.7748 | K39: ft-lb | L39: Mid | M39: 0 | N39: =N34 -> 52.39 | Q39: N IV | R39: =R35*R22*D6 -> -1600.2549 | S39: lb | T39: Upper | U39: -0.1389 | V39: 29.26 | X39: N VIII | Y39: =Y35*Y17*D6 -> 462.29759 | Z39: lb | AA39: Upper | AB39: 0.2 | AC39: 0.0078
A40: U (ft/s) | B40: -15 | C40: -15 | D40: - | E40: 15 | F40: -15 | G40: - | L40: Upper | M40: 0.2 | N40: =N35 -> 43.02 | Q40: C IV | R40: =R36*R22*D6 -> 0 | U40: CNIV | V40: CmIV | X40: C VIII | Y40: =Y36*Y17*D6 -> 20.616171 | Z40: lb | AA40: Extrapolation
A41: Δn (gust) | B41: =R33 -> -1.9702912 | C41: =R46 -> -1.10454 | D41: - | E41: =Y14 -> 0.71969259 | F41: =Y33 -> -0.71969259 | G41: - | M41: CNII | N41: CmII (-) | Q41: MP IV | R41: =R38*R22*D6*D9 -> -2571.9953 | S41: ft-lb | T41: Low | U41: 0.4 | V41: -0.048 | X41: MP VIII | Y41: =Y38*D6*D9*Y17 -> -434.49215 | Z41: ft-lb | AB41: CN VIII | AC41: C.P. VIII (-)
A42: Δn (maneuver) | B42: - | C42: =R47 -> -0.98388723 | D42: - | E42: - | F42: - | G42: - | L42: Low | M42: 0 | N42: =FORECAST(M42,N43:N44,M43:M44) -> -0.03751 | T42: Mid | U42: =R35 -> -0.1086824 | V42: =((U42-U41)/(U43-U41))*(V43-V41)+(V41) -> -0.039835647 | AA42: Low | AB42: 0 | AC42: =FORECAST(AB42,AC43:AC44,AB43:AB44) -> 52.39
...

Sheet ACT 2 v2
V1: EXPLANANTION OF TABLE NO.2 | AI1: EXPLANATION OF TABLE NO. 3
A2: W | B2: 1649.2521 | G2: EXPLANATION OF TABLE NO.1 | W2: TABLE 2 | AJ2: TABLE 3 | AR2: mph
A3: S | B3: 126.521 | D3: n | E3: =(2.1)+((24000)/(10000+B2)) -> 4.1602181 | H3: TABLE 1 | P3: Vcmin (mph) | Q3: =38*(SQRT(B2/B3)) -> 137.19738 | W3: ① | X3: ② | Y3: ③ | AC3: VD | AD3: =(1.5)*(Q3) -> 205.79607 | AJ3: ① | AK3: ② | AL3: ③ | AP3: Clmax | AQ3: =B7+0.5 -> 2.04
A4: W/S | B4: =B2/B3 -> 13.035402 | D4: neg. n | E4: =(-0.4)*E3 -> -1.6640872 | H4: ① | I4: ② | J4: ③ | K4: ④ | L4: ⑤ | W4: V | X4: (+) n | Y4: (-) n | AJ4: V | AK4: (+) n | AL4: (-) n
A5: VS | B5: =(SQRT((B2*2)/(0.002377*B3*B7)))*(3600/5280) -> 57.54013 | H5: V | I5: V | J5: V2 | K5: (+) n | L5: (-) n | P5: Vcdes | Q5: =0.9*B6 -> 125.676 | W5: mph | X5: --- | Y5: --- | AC5: n | AD5: 1 | AE5: (+)/(-) | AF5: =((Q9)*(15)*(Q22))/(575*B4) -> 0.0079975768 | AG5: V | AJ5: mph | AK5: --- | AL5: --- | AP5: Vsl | AQ5: =SQRT((B2/B3)*(2/0.002377)*(1/AQ3)) -> 73.324235
A6: Vmax | B6: 139.64 | D6: VA | E6: =(B5)*(SQRT(E3)) -> 117.36237 | H6: mph | I6: fps | J6: (fps)2 | K6: --- | L6: --- | W6: 0 | X6: =1+($S$24*W6) -> 1 | Y6: =1-($S$24*W6) -> 1 | AJ6: 0 | AK6: =1+($AF$5*AJ6) -> 1 | AL6: =1-($AF$5*AJ6) -> 1
A7: Clmax | B7: 1.54 | D7: (+) CNA | E7: =((E3*B2)/((1/2)*0.002377*B3*(E6*(22/15))^2)) -> 1.54 | H7: 0 | I7: =H7*(22/15) -> 0 | J7: =I7^2 -> 0 | K7: =J7*$E$8 -> 0 | L7: =J7*$E$11 -> 0 | P7: Vc | Q7: =MAX(Q3,Q5) -> 137.19738 | W7: =W6+10 -> 10 | X7: =1+($S$24*W7) -> 1.1599515 | Y7: =1-($S$24*W7) -> 0.84004846 | AC7: At, | AD7: =AD3 -> 205.79607 | AJ7: =AJ6+10 -> 10 | AK7: =1+($AF$5*AJ7) -> 1.0799758 | AL7: =1-($AF$5*AJ7) -> 0.92002423 | AP7: VF | AQ7: =1.4*B5 -> 80.556182 | AR7: mph
D8: (+ )n | E8: =((0.5*E7*0.002377)/(B4)) -> 0.00014040917 | H8: =H7+10 -> 10 | I8: =H8*(22/15) -> 14.666667 | J8: =I8^2 -> 215.11111 | K8: =J8*$E$8 -> 0.030203573 | L8: =J8*$E$11 -> -0.012081429 | W8: =W7+10 -> 20 | X8: =1+($S$24*W8) -> 1.3199031 | Y8: =1-($S$24*W8) -> 0.68009693 | AC8: n | AD8: =1+(AF5*AD7) -> 2.6458699 | AJ8: =AJ7+10 -> 20 | AK8: =1+($AF$5*AJ8) -> 1.1599515 | AL8: =1-($AF$5*AJ8) -> 0.84004846
H9: =H8+10 -> 20 | I9: =H9*(22/15) -> 29.333333 | J9: =I9^2 -> 860.44444 | K9: =J9*$E$8 -> 0.12081429 | L9: =J9*$E$11 -> -0.048325717 | P9: K | Q9: =(1/2)*((B4)^(1/4)) -> 0.95006017 | W9: =W8+10 -> 30 | X9: =1+($S$24*W9) -> 1.4798546 | Y9: =1-($S$24*W9) -> 0.52014539 | AC9: (-) n | AD9: =1-(AF5*AD7) -> -0.64586986 | AJ9: =AJ8+10 -> 30 | AK9: =1+($AF$5*AJ9) -> 1.2399273 | AL9: =1-($AF$5*AJ9) -> 0.76007269 | AP9: VF | AQ9: =1.8*(AQ5*(15/22)) -> 89.988833
D10: ( - ) CNA | E10: =((E4*B2)/((1/2)*0.002377*B3*(E6*(22/15))^2)) -> -0.616 | H10: =H9+10 -> 30 | I10: =H10*(22/15) -> 44 | J10: =I10^2 -> 1936 | K10: =J10*$E$8 -> 0.27183216 | L10: =J10*$E$11 -> -0.10873286 | W10: =W9+10 -> 40 | X10: =1+($S$24*W10) -> 1.6398061 | Y10: =1-($S$24*W10) -> 0.36019385 | AJ10: =AJ9+10 -> 40 | AK10: =1+($AF$5*AJ10) -> 1.3199031 | AL10: =1-($AF$5*AJ10) -> 0.68009693
D11: ( - )n | E11: =((0.5*E10*0.002377)/(B4)) -> -5.6163669e-05 | H11: =H10+10 -> 40 | I11: =H11*(22/15) -> 58.666667 | J11: =I11^2 -> 3441.7778 | K11: =J11*$E$8 -> 0.48325717 | L11: =J11*$E$11 -> -0.19330287 | W11: =W10+10 -> 50 | X11: =1+($S$24*W11) -> 1.7997577 | Y11: =1-($S$24*W11) -> 0.20024232 | AJ11: =AJ10+10 -> 50 | AK11: =1+($AF$5*AJ11) -> 1.3998788 | AL11: =1-($AF$5*AJ11) -> 0.60012116 | AQ11: =MAX(AQ7,AQ9) -> 89.988833
H12: =H11+10 -> 50 | I12: =H12*(22/15) -> 73.333333 | J12: =I12^2 -> 5377.7778 | K12: =J12*$E$8 -> 0.75508932 | L12: =J12*$E$11 -> -0.30203573 | W12: =W11+10 -> 60 | X12: =1+($S$24*W12) -> 1.9597092 | Y12: =1-($S$24*W12) -> 0.040290778 | AJ12: =AJ11+10 -> 60 | AK12: =1+($AF$5*AJ12) -> 1.4798546 | AL12: =1-($AF$5*AJ12) -> 0.52014539
D13: (+ )n | E13: =E8/(10^(-4)) -> 1.4040917 | H13: =H12+10 -> 60 | I13: =H13*(22/15) -> 88 | J13: =I13^2 -> 7744 | K13: =J13*$E$8 -> 1.0873286 | L13: =J13*$E$11 -> -0.43493145 | P13: Cl | Q13: 0.6 | W13: =W12+10 -> 70 | X13: =1+($S$24*W13) -> 2.1196608 | Y13: =1-($S$24*W13) -> -0.11966076 | AJ13: =AJ12+10 -> 70 | AK13: =1+($AF$5*AJ13) -> 1.5598304 | AL13: =1-($AF$5*AJ13) -> 0.44016962
H14: =H13+10 -> 70 | I14: =H14*(22/15) -> 102.66667 | J14: =I14^2 -> 10540.444 | K14: =J14*$E$8 -> 1.4799751 | L14: =J14*$E$11 -> -0.59199003 | P14: AOA | Q14: 6.2127 | W14: =W13+10 -> 80 | X14: =1+($S$24*W14) -> 2.2796123 | Y14: =1-($S$24*W14) -> -0.2796123 | AJ14: =AJ13+10 -> 80 | AK14: =1+($AF$5*AJ14) -> 1.6398061 | AL14: =1-($AF$5*AJ14) -> 0.36019385
D15: ( - )n | E15: =E11/(10^(-5)) -> -5.6163669 | H15: =H14+10 -> 80 | I15: =H15*(22/15) -> 117.33333 | J15: =I15^2 -> 13767.111 | K15: =J15*$E$8 -> 1.9330287 | L15: =J15*$E$11 -> -0.77321147 | W15: =W14+10 -> 90 | X15: =1+($S$24*W15) -> 2.4395638 | Y15: =1-($S$24*W15) -> -0.43956383 | AJ15: =AJ14+10 -> 90 | AK15: =1+($AF$5*AJ15) -> 1.7197819 | AL15: =1-($AF$5*AJ15) -> 0.28021808
H16: =H15+10 -> 90 | I16: =H16*(22/15) -> 132 | J16: =I16^2 -> 17424 | K16: =J16*$E$8 -> 2.4464894 | L16: =J16*$E$11 -> -0.97859576 | P16: Cl | Q16: 0 | W16: =W15+10 -> 100 | X16: =1+($S$24*W16) -> 2.5995154 | Y16: =1-($S$24*W16) -> -0.59951537 | AJ16: =AJ15+10 -> 100 | AK16: =1+($AF$5*AJ16) -> 1.7997577 | AL16: =1-($AF$5*AJ16) -> 0.20024232
H17: =H16+10 -> 100 | I17: =H17*(22/15) -> 146.66667 | J17: =I17^2 -> 21511.111 | K17: =J17*$E$8 -> 3.0203573 | L17: =J17*$E$11 -> -1.2081429 | P17: AOAo | Q17: -1.96 | W17: =W16+10 -> 110 | X17: =1+($S$24*W17) -> 2.7594669 | Y17: =1-($S$24*W17) -> -0.75946691 | AJ17: =AJ16+10 -> 110 | AK17: =1+($AF$5*AJ17) -> 1.8797335 | AL17: =1-($AF$5*AJ17) -> 0.12026655
H18: =H17+10 -> 110 | I18: =H18*(22/15) -> 161.33333 | J18: =I18^2 -> 26028.444 | K18: =J18*$E$8 -> 3.6546323 | L18: =J18*$E$11 -> -1.4618529 | W18: 120 | X18: =1+($S$24*W18) -> 2.9194184 | Y18: =1-($S$24*W18) -> -0.91941844 | AJ18: =AJ17+10 -> 120 | AK18: =1+($AF$5*AJ18) -> 1.9597092 | AL18: =1-($AF$5*AJ18) -> 0.040290778
H19: 117.36 | I19: =H19*(22/15) -> 172.128 | J19: =I19^2 -> 29628.048 | K19: =J19*$E$8 -> 4.1600497 | L19: =J19*$E$11 -> -1.6640199 | R19: 130 | S19: =1+($S$24*R19) -> 3.07937 | T19: =1-($S$24*R19) -> -1.07937 | W19: 130 | X19: =1+($S$24*W19) -> 3.07937 | Y19: =1-($S$24*W19) -> -1.07937 | AE19: 130 | AF19: =1+($AF$5*AE19) -> 2.039685 | AG19: =1-($AF$5*AE19) -> -0.03968499 | AJ19: =AJ18+10 -> 130 | AK19: =1+($AF$5*AJ19) -> 2.039685 | AL19: =1-($AF$5*AJ19) -> -0.03968499
P20: a | Q20: =(Q13/(Q14-Q17)) -> 0.07341515 | W20: 137.19738 | X20: =1+($S$24*W20) -> 3.1944931 | Y20: =1-($S$24*W20) -> -1.1944931 | AJ20: 140 | AK20: =1+($AF$5*AJ20) -> 2.1196608 | AL20: =1-($AF$5*AJ20) -> -0.11966076
D21: graph | H21: 0 | I21: =H21*(22/15) -> 0 | J21: =I21^2 -> 0 | K21: =J21*$E$8 -> 0 | L21: =J21*$E$11 -> 0 | AJ21: 150 | AK21: =1+($AF$5*AJ21) -> 2.1996365 | AL21: =1-($AF$5*AJ21) -> -0.19963653
D22: Va | E22: =(E6/100)*2 -> 2.3472475 | P22: a | Q22: =Q20*(180/PI()) -> 4.2063783 | R22: per rad | AJ22: 160 | AK22: =1+($AF$5*AJ22) -> 2.2796123 | AL22: =1-($AF$5*AJ22) -> -0.2796123
E23: =E22*2 -> 4.694495 | AJ23: 170 | AK23: =1+($AF$5*AJ23) -> 2.3595881 | AL23: =1-($AF$5*AJ23) -> -0.35958806
P24: n | Q24: 1 | R24: (+)/(-) | S24: =((Q9)*(30)*(Q22))/(575*B4) -> 0.015995154 | T24: V | AJ24: 180 | AK24: =1+($AF$5*AJ24) -> 2.4395638 | AL24: =1-($AF$5*AJ24) -> -0.43956383
D25: Vc | E25: =(Q26/100)*2 -> 2.7439476 | AJ25: 190 | AK25: =1+($AF$5*AJ25) -> 2.5195396 | AL25: =1-($AF$5*AJ25) -> -0.5195396
E26: =E25*2 -> 5.4878951 | P26: At, | Q26: =Q7 -> 137.19738 | AJ26: 200 | AK26: =1+($AF$5*AJ26) -> 2.5995154 | AL26: =1-($AF$5*AJ26) -> -0.59951537
P27: n | Q27: =1+(S24*Q26) -> 3.1944931 | AJ27: 205.79607 | AK27: =1+($AF$5*AJ27) -> 2.6458699 | AL27: =1-($AF$5*AJ27) -> -0.64586986
D28: Vd | E28: =(AD3/100)*2 -> 4.1159213 | P28: (-)n | Q28: =1-(S24*Q26) -> -1.1944931
E29: =E28*2 -> 8.2318427
D31: Vs | E31: =(B5/100)*2 -> 1.1508026
E32: =E31*2 -> 2.3016052
D34: Vf | E34: =(AQ11/100)*2 -> 1.7997767
E35: =E34*2 -> 3.5995533
D37: vsl | E37: =(AQ5/100)*2 -> 1.4664847
E38: =E37*2 -> 2.9329694

Sheet ACT 4
I2: No | J2: Item | K2: VL = 138.11 mph | M2: VL = 246.36 mph | P2: Interpolation No.7 (I) | S2: Extrapolation | V2: Interpolation No.7 (III) | Y2: Extrapolation
C3: Constants | F3: Taken from | K3: I | L3: II | M3: III | N3: IV | Q3: CN | R3: CL | T3: CN | U3: CL | W3: CN | X3: CL | Z3: CN | AA3: CL
I4: 1 | J4: W | K4: =D5 -> 1649.2521 | L4: =D5 -> 1649.2521 | M4: =D5 -> 1649.2521 | N4: =D5 -> 1649.2521 | P4: Low | Q4: ='ACT 1'!L9 -> 1.185 | R4: 1.2 | S4: Low | T4: ='ACT 3'!J33 -> -0.32319855 | U4: =FORECAST(T4,U5:U6,T5:T6) -> -0.32319855 | V4: Low | W4: 0.4 | X4: 0.4 | Y4: Low | Z4: ='ACT 3'!R35 -> -0.1086824 | AA4: =FORECAST(Z4,AA5:AA6,Z4:Z6) -> #N/A
C5: W | D5: ='ACT 3'!D5 -> 1649.2521 | E5: lb | F5: ACT 3, AIRDESGN1 | I5: 2 | J5: q | K5: =0.00256*$D$7^2 -> 48.829923 | L5: =0.00256*$D$7^2 -> 48.829923 | M5: =0.00256*$D$11^2 -> 155.37602 | N5: =0.00256*$D$11^2 -> 155.37602 | P5: Mid | Q5: ='ACT 3'!J10 -> 1.319319 | R5: =((Q5-Q4)/(Q6-Q4))*(R6-R4)+(R4) -> 1.3428926 | S5: Mid | T5: 0 | U5: 0 | V5: Mid | W5: ='ACT 3'!R12 -> 0.41462344 | X5: =((W5-W4)/(W6-W4))*(X6-X4)+(X4) -> 0.41462344 | Y5: Mid | Z5: 0 | AA5: 0
C6: S | D6: ='ACT 3'!D6 -> 126.521 | E6: ft^2 | F6: ACT 3, AIRDESGN1 | I6: 3 | J6: W/S | K6: =$K$4/$D$6 -> 13.035402 | L6: =$K$4/$D$6 -> 13.035402 | M6: =$K$4/$D$6 -> 13.035402 | N6: =$K$4/$D$6 -> 13.035402 | P6: Upper | Q6: ='ACT 1'!L10 -> 1.373 | R6: 1.4 | S6: Upper | T6: 0.2 | U6: 0.2 | V6: Upper | W6: 0.6 | X6: 0.6 | Y6: Upper | Z6: 0.2 | AA6: 0.2
C7: VMAX or VL | D7: ='ACT 3'!D12 -> 138.10934 | E7: mph | F7: ACT 11, AIRDESGN1 | I7: 4 | J7: q/(W/S) | K7: =K5/K6 -> 3.7459468 | L7: =L5/L6 -> 3.7459468 | M7: =M5/M6 -> 11.919541 | N7: =N5/N6 -> 11.919541
D8: ='ACT 3'!D13 -> 202.56082 | E8: fps | I8: 5 | J8: n1 | K8: ='ACT 3'!J6 -> 3.9355489 | L8: ='ACT 3'!J32 -> -1.20908 | M8: ='ACT 3'!R10 -> 4.9355489 | N8: ='ACT 3'!R34 -> -0.97029122
C9: VSF | D9: ='ACT 2 v2'!AQ5 -> 73.324235 | E9: fps | F9: ACT 2, AIRDESGN2 | I9: 6 | J9: CN | K9: =K8/K7 -> 1.0506153 | L9: =L8/L7 -> -0.32277021 | M9: =M8/M7 -> 0.41407205 | N9: =N8/N7 -> -0.081403402
D10: =D9*(15/22) -> 49.993796 | E10: mph | I10: 7 | J10: CL correspding to CN | K10: =R5 -> 1.3428926 | L10: =U4 -> -0.32319855 | M10: =X5 -> 0.41462344 | N10: =Z4 -> -0.1086824
C11: Vg | D11: =MAX('ACT 3'!R6:R8) -> 246.36103 | E11: mph | F11: ACT 2, AIRDESGN2 | I11: 8 | J11: CC correspding to CN | K11: ='ACT 3'!J12 -> -0.27665951 | L11: ='ACT 3'!J34 -> 0 | M11: ='ACT 3'!R13 -> 0 | N11: ='ACT 3'!R36 -> 0
D12: =D11*(22/15) -> 361.32951 | E12: fps | I12: 9 | J12: nX1 | K12: =K11*K7 -> -1.0363518 | L12: =L11*L7 -> 0 | M12: =M11*M7 -> 0 | N12: =N11*N7 -> 0
C13: a.c. | D13: ='ACT 3'!D15 -> 0.241 | E13: ft | F13: ACT 1, AIRDESGN2 | I13: 10 | J13: nX4 | K13: =$D$17/K4 -> 0.16051876 | L13: =$D$17/L4 -> 0.16051876 | M13: 0 | N13: 0 | O13: Fpr is assumed "0" for CII & CIV
C14: MAC, c (Wing) | D14: ='ACT 3'!D9 -> 4.3849875 | E14: ft | F14: ACT 2, AIRDESGN1 | I14: 11 | J14: Cm | K14: ='ACT 3'!J14 -> -0.033114907 | L14: ='ACT 3'!J36 -> -0.03983703 | M14: ='ACT 3'!R15 -> -0.0381058 | N14: ='ACT 3'!R38 -> -0.039835647
D15: =D14*0.3048 -> 1.3365442 | E15: m | I15: 12 | J15: m1 | K15: =K14*K7 -> -0.12404668 | L15: =L14*L7 -> -0.14922739 | M15: =M14*M7 -> -0.45420366 | N15: =N14*N7 -> -0.47482265
C16: THPav @ VL | D16: ='[1]ACT 11'!$Q$25 -> 97.5 | E16: hp | F16: ACT 11, AIRDESGN1 | I16: 13 | J16: n3 | K16: =O36 -> -0.13733723 | L16: =M43 -> -0.078183397 | M16: =M46 -> 0.16046421 | N16: =M49 -> -0.19791559
C17: Fpr | D17: =(375*D16)/D7 -> 264.7359 | E17: lb | I17: 14 | J17: n2 | K17: =-K8-K16 -> -3.7982117 | L17: =-L8-L16 -> 1.2872634 | M17: =-M8-M16 -> -5.0960131 | N17: =-N8-N16 -> 1.1682068
C18: MAC, Horizontal | D18: ='[1]ACT 3'!$V$18 -> 0.87283753 | E18: m | I18: 15 | J18: nx2 | K18: =-K12-K13 -> 0.87583304 | L18: =-L12-L13 -> -0.16051876 | M18: =-M12-M13 -> 0 | N18: =-N12-N13 -> 0
C19: MAC, Vertical | D19: ='[1]ACT 3'!$Y$18 -> 0.91317131 | E19: m | I19: 16 | J19: T | K19: =K4*K16 -> -226.50373 | L19: =L4*L16 -> -128.94413 | M19: =M4*M16 -> 264.64594 | N19: =N4*N16 -> -326.41271 | S19: Control Surfaces
I20: 17 | J20: Cmt | S20: A. Balancing Load in Flight
I21: 18 | J21: ΔCm | K21: -0.01 | L21: -0.01 | M21: -0.01 | N21: -0.01 | S21: Pe | T21: {=0.4*MAX(ABS(K25:N25))} -> 160.97403 | U21: lb
B22: Wing | C22: m1 | D22: =0.2*'[1]ACT 3'!$S$16 -> 0.26730884 | E22: m | F22: (20% of MAC from LE) | I22: 19 | J22: Δm1 | K22: =K21*K7 -> -0.037459468 | L22: =L21*L7 -> -0.037459468 | M22: =M21*M7 -> -0.11919541 | N22: =N21*N7 -> -0.11919541 | S22: Ps | T22: {=MAX(ABS(K25:N25))+T21} -> 563.40911 | U22: lb
B23: Horizontal | C23: n3 | D23: =0.2*D18 -> 0.17456751 | E23: m | F23: (20% of MAC from LE) | I23: 20 | J23: Δn3 | K23: =K22/$N$37 -> -0.014486264 | L23: =L22/$N$37 -> -0.014486264 | M23: =M22/$N$37 -> -0.046095054 | N23: =N22/$N$37 -> -0.046095054 | S23: w | T23: =T22/(1.75*'[1]ACT 3'!$U$26) -> 17.845398 | U23: lb/ft^2 | X23: 17.845398 | Y23: =0.15*'[1]ACT 3'!$V$28 -> 0.065603115
I24: 21 | J24: ΔT | K24: =K4*K23 -> -23.891501 | L24: =L4*L23 -> -23.891501 | M24: =M4*M23 -> -76.022367 | N24: =N4*N23 -> -76.022367 | X24: 35.690796 | Y24: =0.45*'[1]ACT 3'!$V$28 -> 0.19680935
I25: 22 | J25: T' | K25: =K19+K24 -> -250.39523 | L25: =L19+L24 -> -152.83564 | M25: =M19+M24 -> 188.62357 | N25: =N19+N24 -> -402.43508 | S25: I1 | T25: =0.15*'[1]ACT 3'!$V$28 -> 0.065603115 | U25: m | X25: 53.536193 | Y25: =0.4*'[1]ACT 3'!$V$28 -> 0.17494164
S26: I2 | T26: =0.45*'[1]ACT 3'!$V$28 -> 0.19680935 | U26: m
C27: Horizontal Stabiliser Chord | S27: I3 | T27: =0.4*'[1]ACT 3'!$V$28 -> 0.17494164 | U27: m
C28: Cs | D28: =D29*3.28084 -> 1.4348888 | E28: ft | I28: Condition I: Forward C.G. Position | M28: Condition I: Aft C.G. Position
D29: 0.4373541 | E29: m | I29: x3 | J29: 3.5421084 | K29: m | M29: x2a | N29: 0.08599057 | O29: m | S29: 3w | T29: =3*T23 -> 53.536193 | U29: lb/ft^2
I30: x3 | J30: =J29/D15 -> 2.6501992 | K30: m | M30: x2a | N30: =N29/D15 -> 0.064337992 | O30: m | S30: 2w | T30: =2*T23 -> 35.690796 | U30: lb/ft^2
I31: x2f | J31: 0.00759057 | K31: m | M31: h2 | N31: 0.01333571 | O31: m
I32: x2f | J32: =J31/D15 -> 0.005679251 | K32: m | M32: h2 | N32: =N31/D15 -> 0.0099777546 | O32: m | S32: B. Maneuvering Loads
I33: h2 | J33: 0.01873571 | K33: m | S33: Kp | T33: =0.15+(5400/(D5+3300)) -> 1.2410739
I34: h2 | J34: =J33/D15 -> 0.014018025 | K34: m | M34: n3 | N34: =(1/(J30+N30))*(K15+(K12*N32)-(K8*N30)+(K13*(J36-N32))) -> -0.13733723 | S34: Vp | T34: =D10+(1.22)*(D7-D10) -> 157.49475 | U34: mph
I35: h4 | J35: 0.1364452 | K35: m | S35: qp | T35: =0.5*0.002377*(22/15)^2*(T34^2) -> 63.415324 | U35: lb/ft^2
I36: h4 | J36: =J35/D15 -> 0.10208806 | K36: m | M36: Therefore, use n3 | O36: =MIN(N34,J38) -> -0.13733723 | S36: -w | T36: =(-0.55)*(T35) -> -34.878428 | U36: lb/ft^2
M37: x3 - x2 | N37: =J30-N30 -> 2.5858612 | O37: m | S37: +w | T37: =(0.35)*(T35) -> 22.195364 | U37: lb/ft^2
I38: n3 | J38: =(1/(J30+J32))*(K15+(K12*J34)-(K8*J32)+(K13*(J36-J34))) -> -0.055269232
S39: C. Vertical Surfaces
S40: w (maneuvering load) | T40: =0.45*T35 -> 28.536896 | U40: lb/ft^2
I41: Condition II: Forward C.G. Position | L41: Condition II: Aft C.G. Position | S41: w (flight gust) | T41: =0.226*D7*(4/(3+(6/2))) -> 20.808473 | U41: lb/ft^2
...

Sheet ACT 5
B4: Constants | E4: Taken From | R4: Interpolation
I5: Table 1 | R5: CL | S5: CN
B6: W | C6: ='ACT 4'!D5 -> 1649.2521 | D6: lb | E6: ACT 3, AIRDESGN1 | I6: A | J6: B | K6: C | L6: D | M6: E | N6: F | O6: G | P6: H | R6: 0.2 | S6: 0.2
C7: ='[1]ACT 3'!$M$8 -> 748.08758 | D7: kg | I7: Strip no. | J7: c | K7: b | L7: S | M7: CL | N7: CN | O7: CND | P7: Rb | R7: 0.22477823 | S7: =((R7-R6)/(R8-R6))*(S8-S6)+(S6) -> 0.22477823
C8: =C7*9.8066 -> 7336.1957 | D8: N | I8: --- | J8: m | K8: m | L8: m2 | M8: --- | N8: --- | O8: --- | P8: --- | R8: 0.4 | S8: 0.4
B9: VL | C9: ='ACT 4'!D7 -> 138.10934 | D9: mph | E9: ACT 11, AIRDESGN1 | I9: 1 | J9: 1.6755 | K9: =$C$13 -> 8.7944608 | L9: =J9*K9 -> 14.735119 | M9: =(2*$C$8)/($C$21*($C$11)^2*L9) -> 0.21324082 | N9: 0.21324852 | O9: 0.39601529 | P9: =N9/O9 -> 0.53848557
C10: ='ACT 4'!D8 -> 202.56082 | D10: fps | I10: 2 | J10: 1.5896 | K10: =$C$13 -> 8.7944608 | L10: =J10*K10 -> 13.979675 | M10: =(2*$C$8)/($C$21*($C$11)^2*L10) -> 0.22476409 | N10: 0.22477823 | O10: 0.39601529 | P10: =N10/O10 -> 0.56759987
C11: =C10*0.3048 -> 61.740538 | D11: mps | I11: 3 | J11: 1.5037 | K11: =$C$13 -> 8.7944608 | L11: =J11*K11 -> 13.224231 | M11: =(2*$C$8)/($C$21*($C$11)^2*L11) -> 0.23760391 | N11: 0.23761971 | O11: 0.39601529 | P11: =N11/O11 -> 0.6000266 | R11: Interpolation
B12: b | C12: ='[1]ACT 3'!$R$18 -> 28.853218 | D12: ft | E12: ACT 3, AIRDESGN1 | I12: 4 | J12: 1.4177 | K12: =$C$13 -> 8.7944608 | L12: =J12*K12 -> 12.467907 | M12: =(2*$C$8)/($C$21*($C$11)^2*L12) -> 0.25201735 | N12: 0.25201735 | O12: 0.39601529 | P12: =N12/O12 -> 0.63638287 | R12: CN | S12: C mac
C13: ='[1]ACT 3'!$S$18 -> 8.7944608 | D13: m | I13: 5 | J13: 1.3318 | K13: =$C$13 -> 8.7944608 | L13: =J13*K13 -> 11.712463 | M13: =(2*$C$8)/($C$21*($C$11)^2*L13) -> 0.26827226 | N13: 0.26827226 | O13: 0.39601529 | P13: =N13/O13 -> 0.67742904 | R13: 0.2 | S13: -0.03787
B14: cr | C14: ='[1]ACT 3'!$R$20 -> 5.6378411 | D14: ft | E14: ACT 3, AIRDESGN1 | I14: 6 | J14: 1.2458 | K14: =$C$13 -> 8.7944608 | L14: =J14*K14 -> 10.956139 | M14: =(2*$C$8)/($C$21*($C$11)^2*L14) -> 0.28679162 | N14: 0.28679162 | O14: 0.39601529 | P14: =N14/O14 -> 0.72419329 | R14: 0.39601529 | S14: =((R14-R13)/(R15-R13))*(S15-S13)+(S13) -> -0.038222828
C15: =C14*0.3048 -> 1.718414 | D15: m | I15: 7 | J15: 1.1599 | K15: =$C$13 -> 8.7944608 | L15: =J15*K15 -> 10.200695 | M15: =(2*$C$8)/($C$21*($C$11)^2*L15) -> 0.30803086 | N15: 0.30803086 | O15: 0.39601529 | P15: =N15/O15 -> 0.77782567 | R15: 0.4 | S15: -0.03823
B16: MAC | C16: ='[1]ACT 3'!$R$16 -> 4.3849875 | D16: ft | E16: ACT 3, AIRDESGN1 | I16: 8 | J16: 1.0741 | K16: =$C$13 -> 8.7944608 | L16: =J16*K16 -> 9.4461304 | M16: =(2*$C$8)/($C$21*($C$11)^2*L16) -> 0.33263662 | N16: 0.33266759 | O16: 0.39601529 | P16: =N16/O16 -> 0.84003724
C17: =C16*0.3048 -> 1.3365442 | D17: m | I17: 9 | J17: 0.988 | K17: =$C$13 -> 8.7944608 | L17: =J17*K17 -> 8.6889273 | M17: =(2*$C$8)/($C$21*($C$11)^2*L17) -> 0.36162449 | N17: 0.36158789 | O17: 0.39601529 | P17: =N17/O17 -> 0.91306548
B18: ct | C18: ='[1]ACT 3'!$R$22 -> 2.8189206 | D18: ft | E18: ACT 3, AIRDESGN1 | I18: 10 | J18: 0.9022 | K18: =$C$13 -> 8.7944608 | L18: =J18*K18 -> 7.9343626 | M18: =(2*$C$8)/($C$21*($C$11)^2*L18) -> 0.39601529 | N18: 0.39601529 | O18: 0.39601529 | P18: =N18/O18 -> 1
C19: =C18*0.3048 -> 0.85920698 | D19: m
B20: a.c. | C20: ='ACT 4'!D13 -> 0.241 | E20: ACT 1, AIRDESGN2 | I20: Table II
B21: ρ | C21: 1.225 | D21: kg/m^3 | I21: 1 | J21: 2 | K21: 3 | L21: 4 | M21: 5 | N21: 6 | O21: 7 | P21: 8 | Q21: 9 | R21: 10 | S21: 11 | T21: 12 | U21: 13 | V21: 14 | W21: 15
I22: Strip No.1 | J22: Y | K22: ΔY | L22: c | M22: cΔY | N22: Rb | O22: RbcΔY | P22: YRbcΔY | Q22: Xac | R22: XacRbcΔY | S22: Zac | T22: ZaccRbcΔY | U22: c2ΔY | V22: Cmac | W22: Cmacc2ΔY
I23: --- | J23: m | K23: m | L23: m | M23: m2 | N23: --- | O23: m2 | P23: m3 | Q23: m | R23: m3 | S23: m | T23: m3 | U23: m3 | V23: --- | W23: m3
B24: MAC | I24: 1 | J24: 0.22 | K24: 0.4397 | L24: 1.6755 | M24: =L24*K24 -> 0.73671735 | N24: =P9 -> 0.53848557 | O24: =N24*M24 -> 0.39671166 | P24: =J24*O24 -> 0.087276566 | Q24: 0.4037 | R24: =Q24*O24 -> 0.1601525 | S24: 0.0152 | T24: =S24*O24 -> 0.0060300173 | U24: =L24*M24 -> 1.2343699 | V24: -0.037893847 | W24: =V24*U24 -> -0.046775025
B25: Cr | C25: =C15*C20 -> 0.41413777 | D25: m | I25: 2 | J25: 0.6594 | K25: 0.8795 | L25: 1.5896 | M25: =L25*K25 -> 1.3980532 | N25: =P10 -> 0.56759987 | O25: =N25*M25 -> 0.79353482 | P25: =J25*O25 -> 0.52325686 | Q25: 0.3831 | R25: =Q25*O25 -> 0.30400319 | S25: 0.0456 | T25: =S25*O25 -> 0.036185188 | U25: =L25*M25 -> 2.2223454 | V25: -0.037914601 | W25: =V25*U25 -> -0.084259337
B26: Ct | C26: =C19*C20 -> 0.20706888 | D26: m | I26: 3 | J26: 1.0989 | K26: 1.3192 | L26: 1.5037 | M26: =L26*K26 -> 1.983681 | N26: =P11 -> 0.6000266 | O26: =N26*M26 -> 1.1902614 | P26: =J26*O26 -> 1.3079782 | Q26: 0.3624 | R26: =Q26*O26 -> 0.43135073 | S26: 0.076 | T26: =S26*O26 -> 0.090459866 | U26: =L26*M26 -> 2.9828612 | V26: -0.037937715 | W26: =V26*U26 -> -0.11316294
I27: 4 | J27: 1.5391 | K27: 1.7589 | L27: 1.4177 | M27: =L27*K27 -> 2.4935925 | N27: =P12 -> 0.63638287 | O27: =N27*M27 -> 1.5868796 | P27: =J27*O27 -> 2.4423664 | Q27: 0.3416 | R27: =Q27*O27 -> 0.54207806 | S27: 0.1064 | T27: =S27*O27 -> 0.16884399 | U27: =L27*M27 -> 3.5351661 | V27: -0.037963631 | W27: =V27*U27 -> -0.13420774
I28: 5 | J28: 1.9788 | K28: 2.1987 | L28: 1.3318 | M28: =L28*K28 -> 2.9282287 | N28: =P13 -> 0.67742904 | O28: =N28*M28 -> 1.9836671 | P28: =J28*O28 -> 3.9252805 | Q28: 0.3209 | R28: =Q28*O28 -> 0.63655879 | S28: 0.1368 | T28: =S28*O28 -> 0.27136566 | U28: =L28*M28 -> 3.8998149 | V28: -0.03799289 | W28: =V28*U28 -> -0.14816524
I29: 6 | J29: 2.4185 | K29: 2.6384 | L29: 1.2458 | M29: =L29*K29 -> 3.2869187 | N29: =P14 -> 0.72419329 | O29: =N29*M29 -> 2.3803645 | P29: =J29*O29 -> 5.7569115 | Q29: 0.3002 | R29: =Q29*O29 -> 0.71458542 | S29: 0.1672 | T29: =S29*O29 -> 0.39799694 | U29: =L29*M29 -> 4.0948433 | V29: -0.038026225 | W29: =V29*U29 -> -0.15571143
I30: 7 | J30: 2.8582 | K30: 3.0781 | L30: 1.1599 | M30: =L30*K30 -> 3.5702882 | N30: =P15 -> 0.77782567 | O30: =N30*M30 -> 2.7770618 | P30: =J30*O30 -> 7.9373981 | Q30: 0.2795 | R30: =Q30*O30 -> 0.77618878 | S30: 0.1977 | T30: =S30*O30 -> 0.54902512 | U30: =L30*M30 -> 4.1411773 | V30: -0.038064456 | W30: =V30*U30 -> -0.15763166
I31: 8 | J31: 3.2976 | K31: 3.5178 | L31: 1.0741 | M31: =L31*K31 -> 3.778469 | N31: =P16 -> 0.84003724 | O31: =N31*M31 -> 3.1740547 | P31: =J31*O31 -> 10.466763 | Q31: 0.2589 | R31: =Q31*O31 -> 0.82176275 | S31: 0.228 | T31: =S31*O31 -> 0.72368446 | U31: =L31*M31 -> 4.0584535 | V31: -0.038108802 | W31: =V31*U31 -> -0.1546628
I32: 9 | J32: 3.7381 | K32: 3.9576 | L32: 0.988 | M32: =L32*K32 -> 3.9101088 | N32: =P17 -> 0.91306548 | O32: =N32*M32 -> 3.5701854 | P32: =J32*O32 -> 13.34571 | Q32: 0.2381 | R32: =Q32*O32 -> 0.85006114 | S32: 0.2585 | T32: =S32*O32 -> 0.92289292 | U32: =L32*M32 -> 3.8631875 | V32: -0.038160858 | W32: =V32*U32 -> -0.14742255
I33: 10 | J33: 4.1774 | K33: 4.3973 | L33: 0.9022 | M33: =L33*K33 -> 3.9672441 | N33: =P18 -> 1 | O33: =N33*M33 -> 3.9672441 | P33: =J33*O33 -> 16.572765 | Q33: 0.2174 | R33: =Q33*O33 -> 0.86247886 | S33: 0.2889 | T33: =S33*O33 -> 1.1461368 | U33: =L33*M33 -> 3.5792476 | V33: -0.038222828 | W33: =V33*U33 -> -0.13680896
I34: Σ | M34: =SUM(M24:M33) -> 28.053302 | O34: =SUM(O24:O33) -> 21.819965 | P34: =SUM(P24:P33) -> 62.365706 | R34: =SUM(R24:R33) -> 6.0992202 | T34: =SUM(T24:T33) -> 4.312621 | U34: =SUM(U24:U33) -> 33.611467 | W34: =SUM(W24:W33) -> -1.2788077
L37: ȳ | M37: =P34/O34 -> 2.8581946 | N37: m | P37: Cmac | Q37: =W34/U34 -> -0.038046768
L38: x̄ | M38: =R34/O34 -> 0.27952475 | N38: m
L39: z̄ | M39: =T34/O34 -> 0.19764564 | N39: m

Sheet ACT 6
C2: Constants | F2: Taken From
C4: W | D4: ='ACT 5'!C6 -> 1649.2521 | E4: lb | F4: ACT 3, AIRDESGN1 | J4: Airload, P | N4: tw | O4: 0.0016 | P4: m
D5: ='[1]ACT 3'!$M$8 -> 748.08758 | E5: kg | J5: n' | K5: =1.5*D21 -> 7.4033234
D6: =9.81*D5 -> 7338.7392 | E6: N | J6: qL | K6: =0.5*D20*(D18)^2 -> 2334.7745 | L6: N/m^2 | O6: Interpolation | R6: Interpolation | U6: Extrapolation
C7: S | D7: ='ACT 4'!D6 -> 126.521 | E7: ft^2 | F7: ACT 11, AIRDESGN1 | J7: CN | K7: =(K5*D6)/(K6*D8) -> 1.9797524 | O7: CN | P7: C.P. | R7: Z/C u | S7: Z/C l | V7: CN | W7: Cp
D8: ='[1]ACT 3'!$S$14 -> 11.754181 | E8: m^2 | J8: P | K8: =K7*K6*D8 -> 54331.059 | L8: N | R8: 70 | S8: 3.05 | U8: Low | V8: 1.9797524 | W8: =FORECAST(V8,W9:W10,V9:V10) -> 26.725621
C9: b | D9: ='ACT 5'!C12 -> 28.853218 | E9: ft | F9: ACT 3, AIRDESGN1 | O9: =K7 -> 1.9797524 | P9: =((O9-O8)/(O10-O8))*(P10-P8)+(P8) -> #DIV/0! | R9: 75 | S9: =((R9-R8)/(R10-R8))*(S10-S8)+(S8) -> 2.6 | U9: Mid | V9: 1.498 | W9: 26.61
D10: ='[1]ACT 3'!$S$18 -> 8.7944608 | E10: m | J10: C.P. | K10: =W8 -> 26.725621 | L10: % | R10: 80 | S10: 2.15 | U10: Upper | V10: 1.373 | W10: 26.58
C11: cr | D11: ='[1]ACT 3'!$R$20 -> 5.6378411 | E11: ft | F11: ACT 3, AIRDESGN1 | J11: c% | K11: Fx-901 | L11: m
D12: =D11*0.3048 -> 1.718414 | E12: m
C13: ct | D13: ='ACT 5'!C18 -> 2.8189206 | E13: ft | F13: ACT 3, AIRDESGN1 | J13: FS | K13: =(P13/100)*(D24) -> 0.26730884 | L13: m | O13: Front Spar | P13: 20 | Q13: %
D14: ='ACT 5'!C19 -> 0.85920698 | E14: m | J14: RS | K14: =(P14/100)*(D24) -> 1.0024081 | L14: m | O14: Rear Spar | P14: 75 | Q14: %
C15: θ | D15: 4.35 | E15: deg | F15: ACT 3, AIRDESGN1
J16: PFS | K16: =(K8*(K14-K11))/(K14-K13) -> #VALUE! | L16: N
C17: VL | D17: ='ACT 5'!C9 -> 138.10934 | E17: mph | F17: ACT 1, AIRDESGN2 | J17: PRS | K17: =ABS(K8-K16) -> #VALUE! | L17: N
D18: =D17*0.44704 -> 61.740398 | E18: mps
C19: ρ | D19: 0.002377 | E19: slug/ft^3 | F19: ACT 1, AIRDESGN2 | J19: For Total Depth of Wing Profile @ 20% MAC | N19: For Total Depth of Wing Profile @ 75% MAC
D20: 1.225 | E20: kg/m^3 | J20: Z/C u | K20: 8.7 | L20: % | N20: Z/C u | O20: 5.255 | P20: % | S20: h FS | T20: =4*(K16/D10) -> #VALUE! | U20: N/m
C21: n, max load factor | D21: ='ACT 3'!J8 -> 4.9355489 | J21: Z/C l | K21: 5.66 | L21: % | N21: Z/C l | O21: 2.6 | P21: % | S21: h RS | T21: =4*(K17/D10) -> #VALUE! | U21: N/m
C23: MAC | D23: ='ACT 5'!C16 -> 4.3849875 | E23: ft | J23: Bending Moment of Wing Root | N23: Bending Moment of Wing Root | S23: Table 1 (Front Spar) | X23: Table 2 (Rear Spar)
D24: ='ACT 5'!C17 -> 1.3365442 | E24: m | J24: dR FS | K24: =((K20/100)+(K21/100))*(D24) -> 0.19192775 | L24: m | N24: dR RS | O24: =((O20/100)+(O21/100))*(D24) -> 0.10498555 | P24: m | S24: 1 | T24: 2 | U24: 3 | V24: 4 | X24: 1 | Y24: 2 | Z24: 3 | AA24: 4
J25: dS FS | K25: =K24-(2*(O4)) -> 0.18872775 | L25: m | N25: dS RS | O25: =O24-(2*(O4)) -> 0.10178555 | P25: m | S25: Strip No. | T25: X | U25: Y | V25: M | X25: Strip No. | Y25: X | Z25: Y | AA25: M
S26: --- | T26: m | U26: N | V26: N-m | X26: --- | Y26: m | Z26: N | AA26: N-m
C27: Span Material | J27: Section Modulus, Z | N27: Section Modulus, Z | S27: A | T27: 0 | U27: 0 | V27: 0 | X27: A | Y27: 0 | Z27: 0 | AA27: 0
C28: Aluminum Allow 7075-T6 | J28: MFS | K28: =K16*'ACT 5'!M37 -> #VALUE! | L28: Nm | N28: MRS | O28: =K17*'ACT 5'!M37 -> #VALUE! | P28: Nm | S28: a-a | T28: {='ACT 5'!K24:K33} -> 0.4397 | U28: =(T28^2)*($T$20/$D$10) -> #VALUE! | V28: =(T28^3)*($T$20/(3*$D$10)) -> #VALUE! | X28: a-a | Y28: =T28 -> 0.4397 | Z28: =(Y28^2)*($T$21/$D$10) -> #VALUE! | AA28: =(Y28^3)*($T$21/(3*$D$10)) -> #VALUE!
C29: Thickness, t | F29: 0.249 | G29: in | J29: ZFS | K29: =K28/F32 -> #VALUE! | L29: m3 | N29: ZRS | O29: =O28/F34 -> #VALUE! | P29: m3 | S29: b-b | T29: 0.8795 | U29: =(T29^2)*($T$20/$D$10) -> #VALUE! | V29: =(T29^3)*($T$20/(3*$D$10)) -> #VALUE! | X29: b-b | Y29: =T29 -> 0.8795 | Z29: =(Y29^2)*($T$21/$D$10) -> #VALUE! | AA29: =(Y29^3)*($T$21/(3*$D$10)) -> #VALUE!
F30: 0.0063 | G30: m | S30: c-c | T30: 1.3192 | U30: =(T30^2)*($T$20/$D$10) -> #VALUE! | V30: =(T30^3)*($T$20/(3*$D$10)) -> #VALUE! | X30: c-c | Y30: =T30 -> 1.3192 | Z30: =(Y30^2)*($T$21/$D$10) -> #VALUE! | AA30: =(Y30^3)*($T$21/(3*$D$10)) -> #VALUE!
C31: Tensile Stress, Fty | F31: 67000 | G31: psi | J31: Area of the Flange of the Front Spar | N31: Area of the Flange of the Front Spar | S31: d-d | T31: 1.7589 | U31: =(T31^2)*($T$20/$D$10) -> #VALUE! | V31: =(T31^3)*($T$20/(3*$D$10)) -> #VALUE! | X31: d-d | Y31: =T31 -> 1.7589 | Z31: =(Y31^2)*($T$21/$D$10) -> #VALUE! | AA31: =(Y31^3)*($T$21/(3*$D$10)) -> #VALUE!
F32: =4.62*10^8 -> 462000000 | G32: Pa | J32: Y FS | K32: =K25/2 -> 0.094363873 | L32: m | N32: Y RS | O32: =O25/2 -> 0.050892773 | P32: m | S32: e-e | T32: 2.1987 | U32: =(T32^2)*($T$20/$D$10) -> #VALUE! | V32: =(T32^3)*($T$20/(3*$D$10)) -> #VALUE! | X32: e-e | Y32: =T32 -> 2.1987 | Z32: =(Y32^2)*($T$21/$D$10) -> #VALUE! | AA32: =(Y32^3)*($T$21/(3*$D$10)) -> #VALUE!
C33: Compressive Stress, Fcy | F33: 68000 | G33: psi | J33: Af FS | K33: =K29/(2*(K25/2)) -> #VALUE! | L33: m2 | N33: Af RS | O33: =O29/(2*O32) -> #VALUE! | P33: m2 | S33: f-f | T33: 2.6384 | U33: =(T33^2)*($T$20/$D$10) -> #VALUE! | V33: =(T33^3)*($T$20/(3*$D$10)) -> #VALUE! | X33: f-f | Y33: =T33 -> 2.6384 | Z33: =(Y33^2)*($T$21/$D$10) -> #VALUE! | AA33: =(Y33^3)*($T$21/(3*$D$10)) -> #VALUE!
F34: =4.69*10^8 -> 4.69e+08 | G34: Pa | S34: g-g | T34: 3.0781 | U34: =(T34^2)*($T$20/$D$10) -> #VALUE! | V34: =(T34^3)*($T$20/(3*$D$10)) -> #VALUE! | X34: g-g | Y34: =T34 -> 3.0781 | Z34: =(Y34^2)*($T$21/$D$10) -> #VALUE! | AA34: =(Y34^3)*($T$21/(3*$D$10)) -> #VALUE!
C35: Form | F35: Extruded "I" Section Shape | J35: Width of the Flange of the Front Spar | N35: Width of the Flange of the Front Spar | S35: g-g | T35: 3.5178 | U35: =(T35^2)*($T$20/$D$10) -> #VALUE! | V35: =(T35^3)*($T$20/(3*$D$10)) -> #VALUE! | X35: g-g | Y35: =T35 -> 3.5178 | Z35: =(Y35^2)*($T$21/$D$10) -> #VALUE! | AA35: =(Y35^3)*($T$21/(3*$D$10)) -> #VALUE!
J36: W FS | K36: =K33/F30 -> #VALUE! | L36: m | N36: W RS | O36: =O33/F30 -> #VALUE! | P36: m | S36: i-i | T36: 3.9576 | U36: =(T36^2)*($T$20/$D$10) -> #VALUE! | V36: =(T36^3)*($T$20/(3*$D$10)) -> #VALUE! | X36: i-i | Y36: =T36 -> 3.9576 | Z36: =(Y36^2)*($T$21/$D$10) -> #VALUE! | AA36: =(Y36^3)*($T$21/(3*$D$10)) -> #VALUE!
S37: B | T37: 4.3973 | U37: =(T37^2)*($T$20/$D$10) -> #VALUE! | V37: =(T37^3)*($T$20/(3*$D$10)) -> #VALUE! | X37: B | Y37: =T37 -> 4.3973 | Z37: =(Y37^2)*($T$21/$D$10) -> #VALUE! | AA37: =(Y37^3)*($T$21/(3*$D$10)) -> #VALUE!
E38: ȳ | F38: 2.8581946 | G38: m | J38: Moment of Inertia | N38: Moment of Inertia
J39: I FS | K39: =2*K33*K32^2 -> #VALUE! | L39: m4 | N39: I RS | O39: =2*O33*(O32^2) -> #VALUE! | P39: m4

Sheet ACT 8
B4: Constants | E4: Taken From
L5: Condition I: Level Landing with Inclined Reactions | S5: Condition II: Level Landing with Nose Wheel Just Clear of Ground | Z5: Condition III: Tail Down Landing
B6: W | C6: ='ACT 6'!D4 -> 1649.2521 | D6: lb | E6: ACT 3, AIRDESGN1 | L6: Basic Landing Conditions (Nose Wheel Type) | S6: A. | T6: Vertical Component | Z6: A. | AA6: Vertical Component
C7: ='[1]ACT 3'!$M$8 -> 748.08758 | D7: kg | H7: nj | I7: 2.5 | L7: A. | M7: Vertical Component | S7: VTL @ C.G | T7: =M8 -> 4431.0517 | U7: lb | Z7: VTL @ C.G | AA7: =T7 -> 4431.0517 | AB7: lb
C8: =9.81*C7 -> 7338.7392 | D8: N | H8: h | I8: =3.6*SQRT('ACT 3'!D7) -> 12.997646 | J8: in | L8: VTL @ C.G | M8: =I12*C9 -> 4431.0517 | N8: lb | S8: B. | T8: Fore and Aft Component @ C.G. = KnWL | Z8: B. | AA8: Fore and Aft Component @ C.G. = KnWL
B9: WL | C9: ='[1]ACT 8'!$I$16 -> 1609.5956 | D9: lb | E9: ACT 7, AIRDESGN2 | H9: L | I9: =2/3 -> 0.66666667 | L9: B. | M9: Fore and Aft Component @ C.G. = KnWL | S9: K | T9: =0.25 -> 0.25 | Z9: FAC @C.G | AA9: 0 | AB9: lb
D10: kg | L10: K | M10: =0.25 -> 0.25 | S10: FAC @C.G | T10: =M11 -> 1107.7629 | U10: lb | Z10: C. | AA10: Lateral Component on either Direction @ C.G.
B11: Vdes | C11: ='[1]ACT 11'!$P$35 -> 202.56036 | D11: fps | E11: ACT 3, AIRDESGN1 | H11: We | I11: =(C9)*((I8+(1-I9)*(C17))/(I8+C17)) -> 1343.1952 | J11: lbb | L11: FAC @C.G | M11: =M10*I12*C9 -> 1107.7629 | N11: lb | S11: C. | T11: Lateral Component on either Direction @ C.G. | Z11: LC @ C.G. | AA11: =T12 -> 0
D12: mps | H12: n | I12: =I7*(I11/C9)+I9 -> 2.7528974 | L12: C. | M12: Lateral Component on either Direction @ C.G. | S12: LC @ C.G. | T12: =M13 -> 0 | Z12: D. | AA12: Shock Abbsorber Extension (Hdraulic)
B13: S | C13: ='[1]ACT 3'!$R$14 -> 126.521 | D13: ft^2 | E13: ACT 11, AIRDESGN1 | L13: LC @ C.G. | M13: =0 -> 0 | S13: D. | T13: Shock Abbsorber Extension (Hdraulic) | AA13: =0.75 -> 0.75
C14: ='[1]ACT 3'!$S$14 -> 11.754181 | D14: m^2 | H14: Ground Reaction Load Factor | L14: D. | M14: Shock Abbsorber Extension (Hdraulic) | T14: =0.75 -> 0.75 | Z14: E. | AA14: Tire Deflection (Static)
B15: b | C15: ='[1]ACT 3'!$R$18 -> 28.853218 | D15: ft | E15: ACT 3, AIRDESGN1 | H15: GRLF | I15: =I12-I9 -> 2.0862308 | M15: =0.75 -> 0.75 | S15: E. | T15: Tire Deflection (Static) | Z15: nt | AA15: =T16 -> 0.47
C16: ='[1]ACT 3'!$S$18 -> 8.7944608 | D16: m | L16: E. | S16: nt | T16: =M17 -> 0.47 | Z16: St | AA16: =T17 -> 3 | AB16: in
B17: d (TOTAL DEFLECTION) | C17: ='[1]ACT 8'!$I$19 -> 4.292471 | D17: in | E17: ACT 7, AIRDESGN2 | L17: nt | M17: 0.47 | S17: St | T17: =M18 -> 3 | U17: in | Z17: TireDef Static | AA17: =T18 -> 1.41 | AB17: in
L18: St | M18: 3 | N18: in | S18: TireDef Static | T18: =M19 -> 1.41 | U18: in | Z18: F. | AA18: Main Wheel Loads (Both Wheels)
B19: Gross Weight C.G. | D19: Condition I&II | L19: TireDef Static | M19: =M17*M18 -> 1.41 | N19: in | S19: F. | T19: Main Wheel Loads (Both Wheels) | Z19: Vr | AA19: =(I12-I9)*C9 -> 3357.9879 | AB19: lb
B20: Aft C.G. | D20: Condition III | L20: F. | M20: Main Wheel Loads (Both Wheels) | S20: Vr | T20: =(I12-I9)*C9 -> 3357.9879 | U20: lb | Z20: Dr | AA20: 0 | AB20: lb
L21: a' | M21: =P21*3.28084 -> 3.7526614 | N21: ft | P21: 1.1438112 | Q21: m | S21: Dr | T21: =T9*I12*C9 -> 1107.7629 | U21: lb | Z21: G. | AA21: Nose Wheel Loads
L22: b' | M22: =P22*3.28084 -> 1.624536 | N22: ft | P22: 0.49515855 | Q22: m | S22: G. | T22: Nose Wheel Loads | Z22: Vf | AA22: 0 | AB22: lb
B23: Nose Wheel | G23: Main Wheel (Condition II) | L23: d' | M23: =P23*3.28084 -> 5.3771974 | N23: ft | P23: 1.6389697 | Q23: m | S23: Vf | T23: 0 | U23: lb | Z23: Df | AA23: 0 | AB23: lb
B24: θ | C24: =DEGREES(ATAN(M10)) -> 14.036243 | D24: deg | G24: β | H24: =DEGREES(ATAN((I12*M10)/(I12-I9))) -> 18.257149 | I24: deg | L24: Vr | M24: =((I12-I9)*C9*M21)/M23 -> 2343.4869 | N24: lb | S24: Df | T24: 0 | U24: lb
B25: cosθ | C25: =COS(C24*(PI()/180)) -> 0.9701425 | G25: Fr | H25: =T21/(SIN(H24*(PI()/180))) -> 3535.9895 | I25: lb | L25: Dr | M25: =(M11*M21)/M23 -> 773.0903 | N25: lb
B26: F | C26: =M8/C25 -> 4567.4235 | D26: lb | L26: G. | M26: Nose Wheel Loads
G27: Tail Down Landing | L27: Vf | M27: =((I12-I9)*C9*M22)/M23 -> 1014.501 | N27: lb
B28: Ff | C28: =M28/(SIN(C24*(PI()/180))) -> 1379.8906 | D28: lb | G28: F | H28: =AA19 -> 3357.9879 | I28: lb | L28: Df | M28: =(M10*I12*C9*M22)/M23 -> 334.67262 | N28: lb
B29: Fr | C29: =M25/(SIN(C24*(PI()/180))) -> 3187.533 | D29: lb
B31: F(checking) | C31: =C28+C29 -> 4567.4235 | D31: lb | E31: (F = Ff + Fr)
