Workbook

Sheet COVER
B2: CONSOLIDATED AIRCRAFT DESIGN WORKBOOK
B3: MK-10
B5: Designer: | C5: Yamanaka, Mark Lorenz B.
B7: Aircraft Design Part 1
B8: ACT 3 | C8: Wing Design & Sizing
B9: ACT 4 | C9: Airfoil Coordinate & Profile Plotting
B10: ACT 5 | C10: Weight Breakdown & Distribution
B11: ACT 6 | C11: Center of Gravity Calculation
B12: ACT 7 | C12: Drag Polar & Power Curves
B13: ACT 8 | C13: Stall & High-Lift Analysis
B14: ACT 9 | C14: Propulsion Performance
B15: ACT 10 | C15: Performance at Altitude (TREQ/THPREQD)
B16: ACT 11 | C16: Rate of Climb & Climb Performance
B17: ACT 12 | C17: Maximum Speed & Power Available
B18: ACT 13 | C18: Service & Absolute Ceiling
B19: ACT 14 | C19: Range & Endurance
B21: Aircraft Design Part 2
B22: ACT 15 | C22: Corrected Airfoil Characteristics
B23: ACT 16 | C23: V-n Diagram (Flight Envelope)
B24: ACT 16 v2 | C24: V-n Diagram — Reference Version
B25: ACT 17 | C25: Gust Load Factors
B26: ACT 18 | C26: Balancing & Maneuvering Loads
B27: ACT 19 | C27: Wing Airload Distribution
B28: ACT 20 | C28: Spar Design & Structural Analysis
B29: ACT 21 | C29: Landing Gear Loads

Sheet ACT 3
A1: Weight | E1: Gross Weight | I1: Wings | L1: Horizontal Tail | O1: Vertical Tail | S1: Wheels | V1: Aileron
A2: Wp | B2: 380 | E2: MTOW | F2: =(B2+B3)/(1-0.5-F7) -> 1649.2521 | H2: lbs | J2: feet | K2: metres | M2: feet | N2: metres | P2: feet | Q2: metres | T2: feet | U2: metres | W2: feet | X2: metres
A3: Weng | B3: 286 | F3: =F2*0.453592 -> 748.08758 | H3: kg | I3: Wing Area (S) | L3: Wing Area (S) | O3: Wing Area (S) | S3: Wing Track | V3: Aileron Gross Area
A4: Wvar/Wto | B4: 0.5 | I4: S | J4: =(2*F2)/(B15*0.002377*(B22^2)) -> 126.521 | K4: =(0.092903)*J4 -> 11.754181 | L4: Sh | M4: =(B17*J4*J6)/(B29) -> 32.801741 | N4: =(0.092903)*M4 -> 3.0473801 | O4: Sv | P4: =((J4*0.04*J8)/(2.65*J6)) -> 12.566161 | Q4: =P4*0.092903 -> 1.1674341 | S4: Wheel Track | T4: =0.27*J8 -> 7.7903688 | U4: =T4*0.3048 -> 2.3745044 | V4: Aileron Area | W4: =(0.07*J4) -> 8.85647 | X4: =W4*0.092903 -> 0.82279264
A5: Wf/Wto | B5: =F7 -> 0.096180607 | I5: Wing Aerodynamic Chord | L5: Tail Span | O5: Tail Span | S5: Tail Span | V5: Aileron Width
E6: Fuel Fraction (Wf/Wto) | I6: c | J6: =SQRT(J4/B12) -> 4.3849875 | K6: =J6*0.3048 -> 1.3365442 | L6: bH | M6: =SQRT(M4*B12) -> 14.691339 | N6: =M6*0.3048 -> 4.4779203 | O6: bT | P6: =SQRT(B30*P4) -> 4.6219557 | Q6: =P6*0.3048 -> 1.4087721 | S6: Wheel Base | T6: =0.28*J14 -> 5.837006 | U6: =T6*0.3048 -> 1.7791194 | V6: Width | W6: =0.25*J6 -> 1.0962469 | X6: =W6*0.3048 -> 0.33413605
E7: Wf/Wto | F7: =B9*(B10/1000)*B11*(B12^-0.5)+0.035 -> 0.096180607 | H7: lbs | I7: Wing Span | L7: Wing Aerodynamic Chord | O7: Wing Aerodnamic Chord | V7: Aileron Length
A8: Constant | F8: =F7*0.453592 -> 0.043626754 | H8: kg | I8: b | J8: =(B12*J6) -> 28.853218 | K8: =J8*0.3048 -> 8.7944608 | L8: cH | M8: =SQRT(M4/B13) -> 2.8636402 | N8: =M8*0.3048 -> 0.87283753 | O8: cV | P8: =SQRT(P4/B14) -> 2.9959689 | Q8: =P8*0.3048 -> 0.91317131 | V8: Length | W8: =(0.35)*(J8/2) -> 5.0493131 | X8: =W8*0.3048 -> 1.5390306
A9: K | B9: 0.31 | I9: Wing Root Chord Cr | L9: Root Chord | O9: Root Chord
A10: R | B10: 375 | E10: Fuel Weight (Wf) | I10: Cr | J10: =(3/2)*(J6)*((B16+1)/((B16^2)+B16+1)) -> 5.6378411 | K10: =J10*0.3048 -> 1.718414 | L10: Crh | M10: =(3/2)*(M8)*((B16+1)/((B16^2)+B16+1)) -> 3.6818231 | N10: =M10*0.3048 -> 1.1222197 | O10: Crv | P10: =(3/2)*(P8)*((B32+1)/((B32^2)+B32+1)) -> 4.06826 | Q10: =P10*0.3048 -> 1.2400057
A11: rUC | B11: 1.35 | E11: Wf | F11: =F7*F2 -> 158.62607 | H11: lbs | I11: Wing Tip Chord | L11: Tip Chord | O11: Tip Chord
A12: A | B12: 6.58 | F12: =F11*0.453592 -> 71.951518 | H12: kg | I12: Ct | J12: =B16*J10 -> 2.8189206 | K12: =J12*0.3048 -> 0.85920698 | L12: Cth | M12: =B16*M10 -> 1.8409116 | N12: =M12*0.3048 -> 0.56110984 | O12: Ctv | P12: =(P10*B32) -> 1.5459388 | Q12: =P12*0.3048 -> 0.47120215 | S12: Flaps | V12: Rudder
A13: Ah | B13: 4 | I13: Overall Length | L13: Elevator Area | O13: Vertical Stabiliser Area | T13: feet | U13: metres | W13: feet | X13: metres
A14: Av | B14: 1.4 | E14: Oil Weight (Wo) | I14: L | J14: =B28*J8 -> 20.84645 | K14: =J14*0.3048 -> 6.3539979 | L14: Elevator Area | M14: =0.45*M4 -> 14.760783 | N14: =M14*0.092903 -> 1.3713211 | O14: VertSta Area | P14: =P4-W15 -> 5.6547726 | Q14: =P14*0.092903 -> 0.52534534 | S14: Flaps Area | V14: Rudder Area
A15: Cl max | B15: 1.54 | E15: Wo | F15: =(1/15)*F11 -> 10.575072 | H15: lbs | L15: Horizontal Stabiliser Area | O15: Propeller Diametre | S15: Area | T15: =(2)*(T16)*(W6) -> 14.406801 | U15: =T15*0.092903 -> 1.338435 | V15: Area | W15: =0.55*P4 -> 6.9113887 | X15: =W15*0.092903 -> 0.64208874
A16: Taper Ratio | B16: 0.5 | F16: =F15*0.453592 -> 4.7967678 | H16: kg | L16: HoriStab Area | M16: =M4-M14 -> 18.040958 | N16: =M16*0.092903 -> 1.6760591 | O16: PropD | P16: =((300/SQRT(B23))*(B20/B21)^1/4) -> 3.2264975 | Q16: =P16*0.3048 -> 0.98343643 | S16: Flaps length | T16: =(0.5)*((0.6)*(J8)-4.17) -> 6.5709654 | U16: =T16*0.3048 -> 2.0028302
A17: Vh | B17: 0.7
E18: Useful Load (Wu)
A19: Power | E19: Wu | F19: =B2+F11+F15 -> 549.20114 | H19: lbs | I19: Power Loading | K19: =F2/B20 -> 13.194017 | M19: note: range is from 12~14
A20: HP | B20: 125 | F20: =F19*0.453592 -> 249.11325 | H20: kg | I20: Wing Loading (W/S) | K20: =F2/J4 -> 13.035402
A21: Velocity | B21: 57.54 | C21: fps | I21: Span Loading | K21: =F2/J8 -> 57.160077 | M21: note: range is from 12~14
B22: =B21*1.46667 -> 84.392192 | C22: mph | E22: Empty Weight (EW) | I22: Standard Engine Dry Weight | K22: =(B3/F2)*100 -> 17.341193 | M22: note: range is from 15~20
A23: RPM | B23: 2550 | E23: EW | F23: =F2-F19 -> 1100.051 | H23: lbs
A24: Payload | F24: =F23*0.453592 -> 498.97433 | H24: kg
AG26: =K8/2 -> 4.3972304
A27: Assumed Values | AG27: =AG26-X8 -> 2.8581998
A28: L/b | B28: 0.7225
A29: Lh | B29: =2.7*(J6) -> 11.839466
A30: A(Vertical Tail) | B30: 1.7
A31: A(Horiz Tail) | B31: 3.5
A32: Taper Ratio (Vert) | B32: 0.38
A33: Taper Ratio (Horiz) | B33: 0.35
A34: Clmax | B34: 1.54
AB40: Wp | AD40: lbs | AI40: 380
AB41: Weng | AD41: lbs | AI41: 286
AB42: Wvar/Wto | AD42: 0.45 or 0.50
AB43: k | AD43: nmi/km | AI43: 0.31
AB44: RANGE | AD44: nmi/km | AI44: 375
AB45: RUC | AD45: fixed gear, no streamlined fairings | AI45: 1.35
AB48: Clmax
...

Sheet ACT 4
B2: NACA 2415: Midterm | J2: Root Chord | R2: Root Chord (scaled)
J3: 1.) Upper Camber | L3: 2.) Lower Camber | N3: 3. X-coordinate | P3: 4. Mean Chord | R3: 1.) Upper Camber | T3: 2.) Lower Camber | V3: 3. X-coordinate | X3: 4. Mean Chord
A4: Upper Surface | C4: Lower Surface | E4: Results
A5: Station | B5: Ordinate | C5: Station | D5: Ordinate | J5: 0 | L5: =(D6*148)/(100) -> 0 | N5: =(A6*148)/(100) -> 0 | P5: 0 | R5: =J5/30 -> 0 | T5: =L5/30 -> 0 | V5: =N5/30 -> 0 | X5: =P5/30 -> 0
A6: 0 | B6: …. | C6: 0 | D6: 0 | J6: =(B7*148)/(100) -> 4.0108 | L6: =(D7*148)/(100) -> -3.0488 | N6: =(A7*148)/(100) -> 1.85 | P6: =((J6+L6)/2) -> 0.481 | R6: =J6/30 -> 0.13369333 | T6: =L6/30 -> -0.10162667 | V6: =N6/30 -> 0.061666667 | X6: =P6/30 -> 0.016033333
A7: 1.25 | B7: 2.71 | C7: 1.25 | D7: -2.06 | J7: =(B8*148)/(100) -> 5.4908 | L7: =(D8*148)/(100) -> -4.2328 | N7: =(A8*148)/(100) -> 3.7 | P7: =((J7+L7)/2) -> 0.629 | R7: =J7/30 -> 0.18302667 | T7: =L7/30 -> -0.14109333 | V7: =N7/30 -> 0.12333333 | X7: =P7/30 -> 0.020966667
A8: 2.5 | B8: 3.71 | C8: 2.5 | D8: -2.86 | G8: 1.) Upper | J8: =(B9*148)/(100) -> 7.5036 | L8: =(D9*148)/(100) -> -5.6832 | N8: =(A9*148)/(100) -> 7.4 | P8: =((J8+L8)/2) -> 0.9102 | R8: =J8/30 -> 0.25012 | T8: =L8/30 -> -0.18944 | V8: =N8/30 -> 0.24666667 | X8: =P8/30 -> 0.03034
A9: 5 | B9: 5.07 | C9: 5 | D9: -3.84 | J9: =(B10*148)/(100) -> 8.9688 | L9: =(D10*148)/(100) -> -6.6156 | N9: =(A10*148)/(100) -> 11.1 | P9: =((J9+L9)/2) -> 1.1766 | R9: =J9/30 -> 0.29896 | T9: =L9/30 -> -0.22052 | V9: =N9/30 -> 0.37 | X9: =P9/30 -> 0.03922
A10: 7.5 | B10: 6.06 | C10: 7.5 | D10: -4.47 | G10: Z(150)/100 | J10: =(B11*148)/(100) -> 10.1084 | L10: =(D11*148)/(100) -> -7.252 | N10: =(A11*148)/(100) -> 14.8 | P10: =((J10+L10)/2) -> 1.4282 | R10: =J10/30 -> 0.33694667 | T10: =L10/30 -> -0.24173333 | V10: =N10/30 -> 0.49333333 | X10: =P10/30 -> 0.047606667 | AL10: ① | AM10: ② | AN10: ③ | AO10: ④ | AP10: ⑤ | AQ10: ⑥ | AR10: ⑦ | AS10: ⑧ | AT10: ⑨ | AU10: ⑩
A11: 10 | B11: 6.83 | C11: 10 | D11: -4.9 | E11: 0 | J11: =(B12*148)/(100) -> 11.7956 | L11: =(D12*148)/(100) -> -8.0216 | N11: =(A12*148)/(100) -> 22.2 | P11: =((J11+L11)/2) -> 1.887 | R11: =J11/30 -> 0.39318667 | T11: =L11/30 -> -0.26738667 | V11: =N11/30 -> 0.74 | X11: =P11/30 -> 0.0629
A12: 15 | B12: 7.97 | C12: 15 | D12: -5.42 | J12: =(B13*148)/(100) -> 12.876 | L12: =(D13*148)/(100) -> -8.3768 | N12: =(A13*148)/(100) -> 29.6 | P12: =((J12+L12)/2) -> 2.2496 | R12: =J12/30 -> 0.4292 | T12: =L12/30 -> -0.27922667 | V12: =N12/30 -> 0.98666667 | X12: =P12/30 -> 0.074986667
A13: 20 | B13: 8.7 | C13: 20 | D13: -5.66 | G13: 2.) Lower | J13: =(B14*148)/(100) -> 13.5716 | L13: =(D14*148)/(100) -> -8.436 | N13: =(A14*148)/(100) -> 37 | P13: =((J13+L13)/2) -> 2.5678 | R13: =J13/30 -> 0.45238667 | T13: =L13/30 -> -0.2812 | V13: =N13/30 -> 1.2333333 | X13: =P13/30 -> 0.085593333 | AL13: 0 | AM13: -1.96 | AN13: =18.24*(-0.015285035)*(AL13) -> 0 | AO13: =AM13+AN13 -> -1.96 | AP13: 0.0084 | AQ13: =0.318*(-0.015285035)*(AL13)^2 -> 0 | AR13: =AP13+AQ13 -> 0.0084 | AS13: =COS(AO13*PI()/180) -> 0.99941495 | AT13: =SIN(AO13*PI()/180) -> -0.034201782 | AU13: =AL13*AS13 -> 0
A14: 25 | B14: 9.17 | C14: 25 | D14: -5.7 | J14: =(B15*148)/(100) -> 13.8824 | L14: =(D15*148)/(100) -> -8.3176 | N14: =(A15*148)/(100) -> 44.4 | P14: =((J14+L14)/2) -> 2.7824 | R14: =J14/30 -> 0.46274667 | T14: =L14/30 -> -0.27725333 | V14: =N14/30 -> 1.48 | X14: =P14/30 -> 0.092746667 | AL14: 0.2 | AM14: 0.99 | AN14: =18.24*(-0.015285035)*(AL14) -> -0.055759808 | AO14: =AM14+AN14 -> 0.93424019 | AP14: 0.0113 | AQ14: =0.318*(-0.015285035)*(AL14)^2 -> -0.00019442565 | AR14: =AP14+AQ14 -> 0.011105574 | AS14: =COS(AO14*PI()/180) -> 0.99986707 | AT14: =SIN(AO14*PI()/180) -> 0.016304845 | AU14: =AL14*AS14 -> 0.19997341
A15: 30 | B15: 9.38 | C15: 30 | D15: -5.62 | G15: Z(150)/100 | J15: =(B16*148)/(100) -> 13.69 | L15: =(D16*148)/(100) -> -7.77 | N15: =(A16*148)/(100) -> 59.2 | P15: =((J15+L15)/2) -> 2.96 | R15: =J15/30 -> 0.45633333 | T15: =L15/30 -> -0.259 | V15: =N15/30 -> 1.9733333 | X15: =P15/30 -> 0.098666667 | AL15: 0.4 | AM15: 3.79 | AN15: =18.24*(-0.015285035)*(AL15) -> -0.11151962 | AO15: =AM15+AN15 -> 3.6784804 | AP15: 0.0192 | AQ15: =0.318*(-0.015285035)*(AL15)^2 -> -0.00077770258 | AR15: =AP15+AQ15 -> 0.018422297 | AS15: =COS(AO15*PI()/180) -> 0.99793979 | AT15: =SIN(AO15*PI()/180) -> 0.064157498 | AU15: =AL15*AS15 -> 0.39917591
A16: 40 | B16: 9.25 | C16: 40 | D16: -5.25 | J16: =(B17*148)/(100) -> 12.6836 | L16: =(D17*148)/(100) -> -6.9116 | N16: =(A17*148)/(100) -> 74 | P16: =((J16+L16)/2) -> 2.886 | R16: =J16/30 -> 0.42278667 | T16: =L16/30 -> -0.23038667 | V16: =N16/30 -> 2.4666667 | X16: =P16/30 -> 0.0962 | AL16: 0.6 | AM16: 6.38 | AN16: =18.24*(-0.015285035)*(AL16) -> -0.16727942 | AO16: =AM16+AN16 -> 6.2127206 | AP16: 0.0307 | AQ16: =0.318*(-0.015285035)*(AL16)^2 -> -0.0017498308 | AR16: =AP16+AQ16 -> 0.028950169 | AS16: =COS(AO16*PI()/180) -> 0.99412696 | AT16: =SIN(AO16*PI()/180) -> 0.10822007 | AU16: =AL16*AS16 -> 0.59647618
A17: 50 | B17: 8.57 | C17: 50 | D17: -4.67 | J17: =(B18*148)/(100) -> 11.1 | L17: =(D18*148)/(100) -> -5.772 | N17: =(A18*148)/(100) -> 88.8 | P17: =((J17+L17)/2) -> 2.664 | R17: =J17/30 -> 0.37 | T17: =L17/30 -> -0.1924 | V17: =N17/30 -> 2.96 | X17: =P17/30 -> 0.0888 | AL17: 0.8 | AM17: 9.03 | AN17: =18.24*(-0.015285035)*(AL17) -> -0.22303923 | AO17: =AM17+AN17 -> 8.8069608 | AP17: 0.0471 | AQ17: =0.318*(-0.015285035)*(AL17)^2 -> -0.0031108103 | AR17: =AP17+AQ17 -> 0.04398919 | AS17: =COS(AO17*PI()/180) -> 0.98820979 | AT17: =SIN(AO17*PI()/180) -> 0.15310589 | AU17: =AL17*AS17 -> 0.79056783
A18: 60 | B18: 7.5 | C18: 60 | D18: -3.9 | G18: 3.) | J18: =(B19*148)/(100) -> 9.028 | L18: =(D19*148)/(100) -> -4.514 | N18: =(A19*148)/(100) -> 103.6 | P18: =((J18+L18)/2) -> 2.257 | R18: =J18/30 -> 0.30093333 | T18: =L18/30 -> -0.15046667 | V18: =N18/30 -> 3.4533333 | X18: =P18/30 -> 0.075233333 | AL18: 1 | AM18: 12.03 | AN18: =18.24*(-0.015285035)*(AL18) -> -0.27879904 | AO18: =AM18+AN18 -> 11.751201 | AP18: 0.071 | AQ18: =0.318*(-0.015285035)*(AL18)^2 -> -0.0048606411 | AR18: =AP18+AQ18 -> 0.066139359 | AS18: =COS(AO18*PI()/180) -> 0.9790412 | AT18: =SIN(AO18*PI()/180) -> 0.20366227 | AU18: =AL18*AS18 -> 0.9790412
A19: 70 | B19: 6.1 | C19: 70 | D19: -3.05 | J19: =(B20*148)/(100) -> 6.5268 | L19: =(D20*148)/(100) -> -3.182 | N19: =(A20*148)/(100) -> 118.4 | P19: =((J19+L19)/2) -> 1.6724 | R19: =J19/30 -> 0.21756 | T19: =L19/30 -> -0.10606667 | V19: =N19/30 -> 3.9466667 | X19: =P19/30 -> 0.055746667 | AL19: 1.2 | AM19: 14.77 | AN19: =18.24*(-0.015285035)*(AL19) -> -0.33455885 | AO19: =AM19+AN19 -> 14.435441 | AP19: 0.0996 | AQ19: =0.318*(-0.015285035)*(AL19)^2 -> -0.0069993232 | AR19: =AP19+AQ19 -> 0.092600677 | AS19: =COS(AO19*PI()/180) -> 0.96842915 | AT19: =SIN(AO19*PI()/180) -> 0.24928897 | AU19: =AL19*AS19 -> 1.162115
A20: 80 | B20: 4.41 | C20: 80 | D20: -2.15 | G20: x(150)/100 | J20: =(B21*148)/(100) -> 3.626 | L20: =(D21*148)/(100) -> -1.7316 | N20: =(A21*148)/(100) -> 133.2 | P20: =((J20+L20)/2) -> 0.9472 | R20: =J20/30 -> 0.12086667 | T20: =L20/30 -> -0.05772 | V20: =N20/30 -> 4.44 | X20: =P20/30 -> 0.031573333 | AL20: 1.4 | AM20: 18.07 | AN20: =18.24*(-0.015285035)*(AL20) -> -0.39031865 | AO20: =AM20+AN20 -> 17.679681 | AP20: 0.1372 | AQ20: =0.318*(-0.015285035)*(AL20)^2 -> -0.0095268566 | AR20: =AP20+AQ20 -> 0.12767314 | AS20: =COS(AO20*PI()/180) -> 0.95276924 | AT20: =SIN(AO20*PI()/180) -> 0.3036952 | AU20: =AL20*AS20 -> 1.3338769
A21: 90 | B21: 2.45 | C21: 90 | D21: -1.17 | J21: =(B22*148)/(100) -> 1.9832 | L21: =(D22*148)/(100) -> -1.0064 | N21: =(A22*148)/(100) -> 140.6 | P21: =((J21+L21)/2) -> 0.4884 | R21: =J21/30 -> 0.066106667 | T21: =L21/30 -> -0.033546667 | V21: =N21/30 -> 4.6866667 | X21: =P21/30 -> 0.01628 | AL21: 1.54 | AM21: 21.9 | AN21: =18.24*(-0.015285035)*(AL21) -> -0.42935052 | AO21: =AM21+AN21 -> 21.470649 | AP21: 0.1898 | AQ21: =0.318*(-0.015285035)*(AL21)^2 -> -0.011527497 | AR21: =AP21+AQ21 -> 0.1782725 | AS21: =COS(AO21*PI()/180) -> 0.93060519 | AT21: =SIN(AO21*PI()/180) -> 0.36602456 | AU21: =AL21*AS21 -> 1.433132
A22: 95 | B22: 1.34 | C22: 95 | D22: -0.68 | G22: 4.) | J22: =(B23*148)/(100) -> 0.2368 | L22: =(D23*148)/(100) -> -0.2368 | N22: =(A23*148)/(100) -> 148 | P22: =((J22+L22)/2) -> 0 | R22: =J22/30 -> 0.0078933333 | T22: =L22/30 -> -0.0078933333 | V22: =N22/30 -> 4.9333333 | X22: =P22/30 -> 0
A23: 100 | B23: 0.16 | C23: 100 | D23: -0.16 | AL23: ⑪ | AM23: ⑫ | AN23: ⑬ | AO23: ⑭ | AP23: ⑮ | AQ23: ⑯ | AR23: ⑰ | AS23: ⑱ | AT23: ⑲ | AU23: ⑳
A24: 100 | B24: …. | C24: 100 | D24: 0 | G24: [(1) + (2)]/2
B25: L.E. radius: 2.48 | J25: Tip Chord | R25: Tip Chord (scaled)
B26: Slope of radius through L.E.: 0.10 | J26: 1.) Upper Camber | L26: 2.) Lower Camber | N26: 3. X-coordinate | P26: 4. Mean Chord | R26: 1.) Upper Camber | T26: 2.) Lower Camber | V26: 3. X-coordinate | X26: 4. Mean Chord | AL26: =AR13+AT13 -> -0.025801782 | AM26: =AU13+AL26 -> -0.025801782 | AN26: =AL13*AT13 -> 0 | AO26: =AR13*AS13 -> 0.0083950856 | AP26: =AO26-AN26 -> 0.0083950856 | AQ26: - | AR26: - | AS26: - | AT26: =(AQ13)/(-0.015285035*6.58) -> 0 | AU26: =AR13-AT26 -> 0.0084
F27: Taper Ratio | G27: =D30/D29 -> 0.5 | AL27: =AR14+AT14 -> 0.027410419 | AM27: =AU14+AL27 -> 0.22738383 | AN27: =AL14*AT14 -> 0.003260969 | AO27: =AR14*AS14 -> 0.011104098 | AP27: =AO27-AN27 -> 0.0078431291 | AQ27: 43.02 | AR27: =(0.25-(AQ27/100))*AM27 -> -0.040974567 | AS27: =AR27+((0.241-0.25)*AM27) -> -0.043021021 | AT27: =(AQ14)/(-0.015285035*6.58) -> 0.0019331307 | AU27: =AR14-AT27 -> 0.0091724437
F28: MAC = | G28: =(2/3)*(D29)*(((G27)^2+(G27)+1)/(G27+1)) -> 115.11111 | J28: 0 | L28: =(D32*84)/(100) -> 0 | N28: =(C6*84)/(100) -> 0 | P28: 0 | R28: =J28/30 -> 0 | T28: =L28/30 -> 0 | V28: =N28/30 -> 0 | X28: =P28/30 -> 0 | AL28: =AR15+AT15 -> 0.082579796 | AM28: =AU15+AL28 -> 0.48175571 | AN28: =AL15*AT15 -> 0.025662999 | AO28: =AR15*AS15 -> 0.018384344 | AP28: =AO28-AN28 -> -0.0072786558 | AQ28: 33.65 | AR28: =(0.25-(AQ28/100))*AM28 -> -0.041671869 | AS28: =AR28+((0.241-0.25)*AM28) -> -0.04600767 | AT28: =(AQ15)/(-0.015285035*6.58) -> 0.0077325228 | AU28: =AR15-AT28 -> 0.010689775
C29: Cr = | D29: 148 | J29: =(B7*84)/(100) -> 2.2764 | L29: =(D7*84)/(100) -> -1.7304 | N29: =(C7*84)/(100) -> 1.05 | P29: =(J29+L29)/2 -> 0.273 | R29: =J29/30 -> 0.07588 | T29: =L29/30 -> -0.05768 | V29: =N29/30 -> 0.035 | X29: =P29/30 -> 0.0091 | AL29: =AR16+AT16 -> 0.13717024 | AM29: =AU16+AL29 -> 0.73364642 | AN29: =AL16*AT16 -> 0.064932042 | AO29: =AR16*AS16 -> 0.028780144 | AP29: =AO29-AN29 -> -0.036151899 | AQ29: 31.2 | AR29: =(0.25-(AQ29/100))*AM29 -> -0.045486078 | AS29: =AR29+((0.241-0.25)*AM29) -> -0.052088896 | AT29: =(AQ16)/(-0.015285035*6.58) -> 0.017398176 | AU29: =AR16-AT29 -> 0.011551993
C30: Ct = | D30: 74 | E30: ← corrected: Ct = Cr × λ = 148 × 0.50 = 74 (was 84, gave λ=0.568 inconsistent with ACT 3) | J30: =(B8*84)/(100) -> 3.1164 | L30: =(D8*84)/(100) -> -2.4024 | N30: =(C8*84)/(100) -> 2.1 | P30: =(J30+L30)/2 -> 0.357 | R30: =J30/30 -> 0.10388 | T30: =L30/30 -> -0.08008 | V30: =N30/30 -> 0.07 | X30: =P30/30 -> 0.0119 | AL30: =AR17+AT17 -> 0.19709508 | AM30: =AU17+AL30 -> 0.98766291 | AN30: =AL17*AT17 -> 0.12248471 | AO30: =AR17*AS17 -> 0.043470548 | AP30: =AO30-AN30 -> -0.079014167 | AQ30: 30.12 | AR30: =(0.25-(AQ30/100))*AM30 -> -0.050568341 | AS30: =AR30+((0.241-0.25)*AM30) -> -0.059457307 | AT30: =(AQ17)/(-0.015285035*6.58) -> 0.030930091 | AU30: =AR17-AT30 -> 0.013059098
J31: =(B9*84)/(100) -> 4.2588 | L31: =(D9*84)/(100) -> -3.2256 | N31: =(C9*84)/(100) -> 4.2 | P31: =(J31+L31)/2 -> 0.5166 | R31: =J31/30 -> 0.14196 | T31: =L31/30 -> -0.10752 | V31: =N31/30 -> 0.14 | X31: =P31/30 -> 0.01722 | AL31: =AR18+AT18 -> 0.26980163 | AM31: =AU18+AL31 -> 1.2488428 | AN31: =AL18*AT18 -> 0.20366227 | AO31: =AR18*AS18 -> 0.064753158 | AP31: =AO31-AN31 -> -0.13890912 | AQ31: 29.26 | AR31: =(0.25-(AQ31/100))*AM31 -> -0.053200705 | AS31: =AR31+((0.241-0.25)*AM31) -> -0.06444029 | AT31: =(AQ18)/(-0.015285035*6.58) -> 0.048328267 | AU31: =AR18-AT31 -> 0.017811091
J32: =(B10*84)/(100) -> 5.0904 | L32: =(D10*84)/(100) -> -3.7548 | N32: =(C10*84)/(100) -> 6.3 | P32: =(J32+L32)/2 -> 0.6678 | R32: =J32/30 -> 0.16968 | T32: =L32/30 -> -0.12516 | V32: =N32/30 -> 0.21 | X32: =P32/30 -> 0.02226 | AL32: =AR19+AT19 -> 0.34188965 | AM32: =AU19+AL32 -> 1.5040046 | AN32: =AL19*AT19 -> 0.29914677 | AO32: =AR19*AS19 -> 0.089677194 | AP32: =AO32-AN32 -> -0.20946957 | AQ32: 27.05 | AR32: =(0.25-(AQ32/100))*AM32 -> -0.030832095 | AS32: =AR32+((0.241-0.25)*AM32) -> -0.044368136 | AT32: =(AQ19)/(-0.015285035*6.58) -> 0.069592705 | AU32: =AR19-AT32 -> 0.023007972
F33: 118.94253 | J33: =(B11*84)/(100) -> 5.7372 | L33: =(D11*84)/(100) -> -4.116 | N33: =(C11*84)/(100) -> 8.4 | P33: =(J33+L33)/2 -> 0.8106 | R33: =J33/30 -> 0.19124 | T33: =L33/30 -> -0.1372 | V33: =N33/30 -> 0.28 | X33: =P33/30 -> 0.02702 | AL33: =AR20+AT20 -> 0.43136835 | AM33: =AU20+AL33 -> 1.7652453 | AN33: =AL20*AT20 -> 0.42517328 | AO33: =AR20*AS20 -> 0.12164304 | AP33: =AO33-AN33 -> -0.30353024 | AQ33: 26.58 | AR33: =(0.25-(AQ33/100))*AM33 -> -0.027890875 | AS33: =AR33+((0.241-0.25)*AM33) -> -0.043778083 | AT33: =(AQ20)/(-0.015285035*6.58) -> 0.094723404 | AU33: =AR20-AT33 -> 0.032949739
J34: =(B12*84)/(100) -> 6.6948 | L34: =(D12*84)/(100) -> -4.5528 | N34: =(C12*84)/(100) -> 12.6 | P34: =(J34+L34)/2 -> 1.071 | R34: =J34/30 -> 0.22316 | T34: =L34/30 -> -0.15176 | V34: =N34/30 -> 0.42 | X34: =P34/30 -> 0.0357 | AL34: =AR21+AT21 -> 0.54429706 | AM34: =AU21+AL34 -> 1.9774291 | AN34: =AL21*AT21 -> 0.56367782 | AO34: =AR21*AS21 -> 0.16590132 | AP34: =AO34-AN34 -> -0.39777651 | AQ34: 26.61 | AR34: =(0.25-(AQ34/100))*AM34 -> -0.031836608 | AS34: =AR34+((0.241-0.25)*AM34) -> -0.049633469 | AT34: =(AQ21)/(-0.015285035*6.58) -> 0.11461532 | AU34: =AR21-AT34 -> 0.063657184
J35: =(B13*84)/(100) -> 7.308 | L35: =(D13*84)/(100) -> -4.7544 | N35: =(C13*84)/(100) -> 16.8 | P35: =(J35+L35)/2 -> 1.2768 | R35: =J35/30 -> 0.2436 | T35: =L35/30 -> -0.15848 | V35: =N35/30 -> 0.56 | X35: =P35/30 -> 0.04256
J36: =(B14*84)/(100) -> 7.7028 | L36: =(D14*84)/(100) -> -4.788 | N36: =(C14*84)/(100) -> 21 | P36: =(J36+L36)/2 -> 1.4574 | R36: =J36/30 -> 0.25676 | T36: =L36/30 -> -0.1596 | V36: =N36/30 -> 0.7 | X36: =P36/30 -> 0.04858
J37: =(B15*84)/(100) -> 7.8792 | L37: =(D15*84)/(100) -> -4.7208 | N37: =(C15*84)/(100) -> 25.2 | P37: =(J37+L37)/2 -> 1.5792 | R37: =J37/30 -> 0.26264 | T37: =L37/30 -> -0.15736 | V37: =N37/30 -> 0.84 | X37: =P37/30 -> 0.05264
J38: =(B16*84)/(100) -> 7.77 | L38: =(D16*84)/(100) -> -4.41 | N38: =(C16*84)/(100) -> 33.6 | P38: =(J38+L38)/2 -> 1.68 | R38: =J38/30 -> 0.259 | T38: =L38/30 -> -0.147 | V38: =N38/30 -> 1.12 | X38: =P38/30 -> 0.056
J39: =(B17*84)/(100) -> 7.1988 | L39: =(D17*84)/(100) -> -3.9228 | N39: =(C17*84)/(100) -> 42 | P39: =(J39+L39)/2 -> 1.638 | R39: =J39/30 -> 0.23996 | T39: =L39/30 -> -0.13076 | V39: =N39/30 -> 1.4 | X39: =P39/30 -> 0.0546
J40: =(B18*84)/(100) -> 6.3 | L40: =(D18*84)/(100) -> -3.276 | N40: =(C18*84)/(100) -> 50.4 | P40: =(J40+L40)/2 -> 1.512 | R40: =J40/30 -> 0.21 | T40: =L40/30 -> -0.1092 | V40: =N40/30 -> 1.68 | X40: =P40/30 -> 0.0504
J41: =(B19*84)/(100) -> 5.124 | L41: =(D19*84)/(100) -> -2.562 | N41: =(C19*84)/(100) -> 58.8 | P41: =(J41+L41)/2 -> 1.281 | R41: =J41/30 -> 0.1708 | T41: =L41/30 -> -0.0854 | V41: =N41/30 -> 1.96 | X41: =P41/30 -> 0.0427
...

Sheet ACT 5
A1: Items | B1: Weight Range | C1: Detailed Weight | D1: Weight | E1: Weight | I1: change to wat u like
B2: % | C2: % | D2: (lb) | E2: (kg) | I2: dont touch
A3: I. Payload | B3: 30 - 35 | C3: =(D3/$D$31)*100 -> 32.817494 | D3: =SUM(D4:D8) -> 549.20114 | E3: =D3/2.2 -> 249.63688 | F3: [Note: "Payload" here includes fuel & oil per Loftin method convention. In standard practice, payload = crew + baggage only; fuel/oil are separate variable weight items.]
A4: 1. Pilot | C4: =(D4/$D$31)*100 -> 10.158344 | D4: 170 | E4: =D4/2.2 -> 77.272727
A5: 2. Passenger(s) | C5: =(D5/$D$31)*100 -> 10.158344 | D5: 170 | E5: =D5/2.2 -> 77.272727
A6: 3. Baggage | C6: =(D6/$D$31)*100 -> 2.3901985 | D6: 40 | E6: =D6/2.2 -> 18.181818 | L6: Fuel | P6: 134.37396
A7: 4. Fuel | C7: =(D7/$D$31)*100 -> 9.4786952 | D7: ='ACT 3'!F11 -> 158.62607 | E7: =D7/2.2 -> 72.10276 | F7: ← linked to ACT 3 Loftin fuel (was 134.37 lb; ACT 3 Wf = 158.6 lb) | L7: Oil | P7: 10.575072
A8: 5. Oil | C8: =(D8/$D$31)*100 -> 0.63191301 | D8: ='ACT 3'!F15 -> 10.575072 | E8: =D8/2.2 -> 4.8068507 | F8: ← linked to ACT 3 oil weight formula | L8: Wing | P8: 210
A9: II. Empty Weight | B9: 65 - 70 | C9: =(D9/$D$31)*100 -> 67.182506 | D9: =D31-D3 -> 1124.3 | E9: =D9/2.2 -> 511.04545 | L9: Fuselage inluding canopy | P9: 180
A10: A. Airframe | B10: 30 - 35 | C10: =(D10/$D$31)*100 -> 31.042704 | D10: =SUM(D11:D17) -> 519.5 | E10: =D10/2.2 -> 236.13636 | L10: Horizontal Tail, including Elevators | P10: 33
A11: 6. Wing | B11: 12 to 15 | C11: =(D11/$D$31)*100 -> 12.548542 | D11: 210 | E11: =D11/2.2 -> 95.454545 | L11: Vertical Tail, including Rudder | P11: 32
A12: 7. Fuselage, including canopy | B12: 9 to 12 | C12: =(D12/$D$31)*100 -> 10.755893 | D12: 180 | E12: =D12/2.2 -> 81.818182 | L12: Cowling | P12: 16.5
A13: 8. Horizontal tail including elevator(s) | B13: 1.5-2 | C13: =(D13/$D$31)*100 -> 1.9719138 | D13: 33 | E13: =D13/2.2 -> 15 | L13: Flaps and Ailerons | P13: 32
A14: 9. Vertical tail including rudder | B14: 1.5-2 | C14: =(D14/$D$31)*100 -> 1.9121588 | D14: 32 | E14: =D14/2.2 -> 14.545455 | L14: Trim Tabs | P14: 16
A15: 10. Cowling | B15: 1 | C15: =(D15/$D$31)*100 -> 0.9859569 | D15: 16.5 | E15: =D15/2.2 -> 7.5 | L15: Landing Gears | P15: 92.6
A16: 11. Flaps and Ailerons | B16: 1.5-2 | C16: =(D16/$D$31)*100 -> 1.9121588 | D16: 32 | E16: =D16/2.2 -> 14.545455 | L16: Fuel Tank(s) and System | P16: 49
A17: 12. Trim Tabs | B17: 0.5-1 | C17: =(D17/$D$31)*100 -> 0.95607942 | D17: 16 | E17: =D17/2.2 -> 7.2727273 | L17: Flaps and Ailerons Control | P17: 24
A18: B. Aircraft Systems | B18: 15-17 | C18: =(D18/$D$31)*100 -> 15.363001 | D18: =SUM(D19,D20,D21,D22,D26,D27) -> 257.1 | E18: =D18/2.2 -> 116.86364 | L18: Instruments and Radio | P18: 33.5
A19: 13. Landing gears | B19: 5 to 6 | C19: =(D19/$D$31)*100 -> 5.5333096 | D19: 92.6 | E19: =D19/2.2 -> 42.090909 | L19: Battery Lights and Electrical System | P19: 34
A20: 14. Fuel tank(s) and system | B20: 2.5-3 | C20: =(D20/$D$31)*100 -> 2.9279932 | D20: 49 | E20: =D20/2.2 -> 22.272727 | L20: Seats and Harnesses | P20: 24
A21: 15. Flaps and ailerons control | B21: 1-1.5 | C21: =(D21/$D$31)*100 -> 1.4341191 | D21: 24 | E21: =D21/2.2 -> 10.909091 | L21: Standard Engine Dry Weight | P21: 285.7
A22: 16. Instruments and radio | B22: 2-2.5 | C22: =(D22/$D$31)*100 -> 2.0017913 | D22: =SUM(D23:D25) -> 33.5 | E22: =D22/2.2 -> 15.227273 | L22: Propeller and Spinner | P22: 62
A23: I. BendixKing KY 196 VHF Radio) | C23: =(D23/$D$31)*100 -> 0.20914237 | D23: 3.5 | E23: =D23/2.2 -> 1.5909091
A24: II. Garmin GNS 430W GPS/NAV/COM | C24: =(D24/$D$31)*100 -> 1.0755893 | D24: 18 | E24: =D24/2.2 -> 8.1818182
A25: III. Garmin G5 Attitude Indicator | C25: =(D25/$D$31)*100 -> 0.71705956 | D25: 12 | E25: =D25/2.2 -> 5.4545455
A26: 17. Battery lights and electrical system | B26: 2-2.5 | C26: =(D26/$D$31)*100 -> 2.0316688 | D26: 34 | E26: =D26/2.2 -> 15.454545
A27: 18. Seats and harnesses | B27: 1-1.5 | C27: =(D27/$D$31)*100 -> 1.4341191 | D27: 24 | E27: =D27/2.2 -> 10.909091
A28: C. Propulsion group | B28: 20-25 | C28: =(D28/$D$31)*100 -> 20.776801 | D28: =SUM(D29:D30) -> 347.7 | E28: =D28/2.2 -> 158.04545
A29: 19. Standard engine dry weight | B29: 15-20 | C29: =(D29/$D$31)*100 -> 17.071993 | D29: 285.7 | E29: =D29/2.2 -> 129.86364
A30: 20. Propeller and spinner | B30: 3 to 5 | C30: =(D30/$D$31)*100 -> 3.7048077 | D30: 62 | E30: =D30/2.2 -> 28.181818
A31: III. Gross Weight | C31: 100 | D31: =SUM(D28,D18,D10,D3) -> 1673.5011 | E31: =D31/2.2 -> 760.68234
D33: 1649.25
D35: =D33-D31 -> -24.251144

Sheet ACT 6
D4: PROP AND SPINNER GROUP
D5: PORTION | E5: A | F5: X | G5: Y | H5: AX | I5: AY
E6: m^2 | F6: m | G6: m | H6: m^3 | I6: m^3 | K6: X' | L6: =H9/E9 -> 0.2048087
D7: PROPELLER | E7: 0.0245 | F7: 0.2377 | G7: 1.1001 | H7: =E7*F7 -> 0.00582365 | I7: =E7*G7 -> 0.02695245 | K7: Y' | L7: =ROUND(I9/E9,4) -> 1.101
D8: SPINNER | E8: 0.0445 | F8: 0.1867 | G8: 1.1015 | H8: =E8*F8 -> 0.00830815 | I8: =E8*G8 -> 0.04901675
E9: =SUM(E7:E8) -> 0.069 | H9: =SUM(H7:H8) -> 0.0141318 | I9: =SUM(I7:I8) -> 0.0759692
D13: ENGINE GROUP
D14: PORTION | E14: A | F14: X | G14: Y | H14: AX | I14: AY
E15: m^2 | F15: m | G15: m | H15: m^3 | I15: m^3 | K15: X' | L15: =H18/E18 -> 0.86790311
D16: ENGINE | E16: 0.4087 | F16: 0.8304 | G16: 0.9394 | H16: =E16*F16 -> 0.33938448 | I16: =E16*G16 -> 0.38393278 | K16: Y' | L16: =ROUND(I18/E18,4) -> 0.9278
D17: COWLING | E17: 0.7943 | F17: 0.8872 | G17: 0.9218 | H17: =E17*F17 -> 0.70470296 | I17: =E17*G17 -> 0.73218574
E18: =SUM(E16:E17) -> 1.203 | H18: =SUM(H16:H17) -> 1.0440874 | I18: =SUM(I16:I17) -> 1.1161185
D22: FUSELAGE GROUP
D23: PORTION | E23: A | F23: X | G23: Y | H23: AX | I23: AY
E24: m^2 | F24: m | G24: m | H24: m^3 | I24: m^3 | K24: X' | L24: =H32/E32 -> 2.9221472
D25: FUSELAGE | E25: 3.2502 | F25: 3.1208 | G25: 1.1104 | H25: =E25*F25 -> 10.143224 | I25: =E25*G25 -> 3.6090221 | K25: Y' | L25: =ROUND(I32/E32,4) -> 1.1258
D26: CANOPY | E26: 0.281 | F26: 2.379 | G26: 1.3902 | H26: =E26*F26 -> 0.668499 | I26: =E26*G26 -> 0.3906462
D27: INSTRU | E27: 0.1742 | F27: 1.6186 | G27: 1.1494 | H27: =E27*F27 -> 0.28196012 | I27: =E27*G27 -> 0.20022548
D28: BATTS | E28: 0.03 | F28: 1.36 | G28: 1.14 | H28: =E28*F28 -> 0.0408 | I28: =E28*G28 -> 0.0342
D29: SEATS | E29: 0.11 | F29: 2.31 | G29: 1.03 | H29: =E29*F29 -> 0.2541 | I29: =E29*G29 -> 0.1133
D30: PILOT | E30: 0.15 | F30: 2.11 | G30: 1.14 | H30: =E30*F30 -> 0.3165 | I30: =E30*G30 -> 0.171
D31: BAGGAGE | E31: 0.11 | F31: 2.65 | G31: 0.94 | H31: =E31*F31 -> 0.2915 | I31: =E31*G31 -> 0.1034
E32: =SUM(E25:E31) -> 4.1054 | H32: =SUM(H25:H31) -> 11.996583 | I32: =SUM(I25:I31) -> 4.6217938
D36: WING GROUP
D37: PORTION | E37: A | F37: X | G37: Y | H37: AX | I37: AY
E38: m^2 | F38: m | G38: m | H38: m^3 | I38: m^3 | K38: X' | L38: =H42/E42 -> 2.2998549 | O38: Propeller and Spinner Group
D39: WING | E39: 0.4616 | F39: 2.2139 | G39: 0.7401 | H39: =E39*F39 -> 1.0219362 | I39: =E39*G39 -> 0.34163016 | K39: Y' | L39: =ROUND(I42/E42,4) -> 0.7717 | Q39: Area | R39: =E9 -> 0.069 | S39: ← total area corrected: SUM(E7:E8)=0.069 (was hardcoded 0.0661)
D40: FLAP-AILERONS | E40: 0.1 | F40: 2.65 | G40: 0.92 | H40: =E40*F40 -> 0.265 | I40: =E40*G40 -> 0.092 | Q40: X | R40: =L6 -> 0.2048087 | S40: ← X′ corrected: prop/spinner centroid ~0.21 m forward (was engine value 0.87 m)
D41: TRIMS | E41: 0.0056 | F41: 3.1324 | G41: 0.7288 | H41: =E41*F41 -> 0.01754144 | I41: =E41*G41 -> 0.00408128 | Q41: Y | R41: =L7 -> 1.101 | S41: ← Y′ corrected: ~1.10 m (was engine value 0.93 m)
E42: =SUM(E39:E41) -> 0.5672 | H42: =SUM(H39:H41) -> 1.3044777 | I42: =SUM(I39:I41) -> 0.43771144 | P42: Engine Group | Q42: Area | R42: 1.203
Q43: X | R43: 0.86790311
Q44: Y | R44: 0.9278
P45: Fuselage Group | Q45: Area | R45: =SUM(R38:R44) -> 4.3735118
D46: HORIZONTAL STABILIZER | Q46: X | R46: 2.9221472
D47: PORTION | E47: A | F47: X | G47: Y | H47: AX | I47: AY | K47: X' | L47: =H52/E52 -> 5.6362017 | Q47: Y | R47: 1.1258
E48: m^2 | F48: m | G48: m | H48: m^3 | I48: m^3 | K48: Y' | L48: =ROUND(I52/E52,4) -> 1.3402 | P48: Wing Group | Q48: Area | R48: 0.5672
D49: Horizontal Stabilizer | E49: 0.0629 | F49: 5.5737 | G49: 1.386 | H49: =E49*F49 -> 0.35058573 | I49: =E49*G49 -> 0.0871794 | Q49: X | R49: 2.2998549
D50: ELEVATOR | E50: 0.0157 | F50: 5.8361 | G50: 1.1787 | H50: =E50*F50 -> 0.09162677 | I50: =E50*G50 -> 0.01850559 | Q50: Y | R50: 0.7717
D51: TRIMS | E51: 0.0021 | F51: 6.0138 | G51: 1.1744 | H51: =E51*F51 -> 0.01262898 | I51: =E51*G51 -> 0.00246624 | P51: Horizontal Tail Group | Q51: Area | R51: 0.0807
E52: =SUM(E49:E51) -> 0.0807 | H52: =SUM(H49:H51) -> 0.45484148 | I52: =SUM(I49:I51) -> 0.10815123 | Q52: X | R52: 5.6362017
...

Sheet ACT 7
G7: Fuselage including Canopy | N7: X' | O7: =K12/H12 -> 3.3070628
G8: PORTION | H8: A | I8: X | J8: Y | K8: AX | L8: AY | N8: Y' | O8: =ROUND(L12/H12,4) -> 1.141
H9: m^2 | I9: m | J9: m | K9: m^3 | L9: m^3
G10: FUSELAGE | H10: ='ACT 6'!E25 -> 3.2502 | I10: ='ACT 6'!F25 -> 3.1208 | J10: ='ACT 6'!G25 -> 1.1104 | K10: 11.0143 | L10: 3.6146
G11: CANOPY | H11: ='ACT 6'!E26 -> 0.281 | I11: ='ACT 6'!F26 -> 2.379 | J11: ='ACT 6'!G26 -> 1.3902 | K11: 0.6636 | L11: 0.4144
G12: ∑ | H12: =SUM(H10:H11) -> 3.5312 | K12: =SUM(K10:K11) -> 11.6779 | L12: =SUM(L10:L11) -> 4.029
G15: Vertical Tail including Rudder | N15: X' | O15: =K20/H20 -> 5.4724373
G16: PORTION | H16: A | I16: X | J16: Y | K16: AX | L16: AY | N16: Y' | O16: =ROUND(L20/H20,4) -> 1.5529
H17: m^2 | I17: m | J17: m | K17: m^3 | L17: m^3
G18: VERTICAL STABILIZER | H18: ='ACT 6'!E58 -> 1.0064 | I18: ='ACT 6'!F58 -> 5.7417 | J18: ='ACT 6'!G58 -> 1.7092 | K18: 5.3388 | L18: 1.5318
G19: RUDDER | H19: ='ACT 6'!E59 -> 0.2979 | I19: ='ACT 6'!F59 -> 6.0387 | J19: ='ACT 6'!G59 -> 1.6568 | K19: 1.7989 | L19: 0.4936
G20: ∑ | H20: =SUM(H18:H19) -> 1.3043 | K20: =SUM(K18:K19) -> 7.1377 | L20: =SUM(L18:L19) -> 2.0254
G23: Horizontal Tail including Elevator | N23: X' | O23: =K28/H28 -> 6.1564885
G24: PORTION | H24: A | I24: X | J24: Y | K24: AX | L24: AY | N24: Y' | O24: =ROUND(L28/H28,4) -> 1.1005 | AG24: Basic Airplane | AH24: W, Weight | AI24: kg | AK24: 500.27273
H25: m^2 | I25: m | J25: m | K25: m^3 | L25: m^3 | AH25: X, Horizontal Arm | AI25: m | AK25: 2.0241759
G26: HORIZONTAL TAIL STABILIZER | H26: ='ACT 6'!E49 -> 0.0629 | I26: ='ACT 6'!F49 -> 5.5737 | J26: ='ACT 6'!G49 -> 1.386 | K26: 0.3456 | L26: 0.0624 | AH26: Y, Vertical Arm | AI26: m | AK26: 0.9443
G27: ELEVATOR | H27: ='ACT 6'!E50 -> 0.0157 | I27: ='ACT 6'!F50 -> 5.8361 | J27: ='ACT 6'!G50 -> 1.1787 | K27: 0.1383 | L27: 0.0241 | AG27: Pilot | AH27: W, Weight | AI27: kg | AK27: 77.1
G28: ∑ | H28: =SUM(H26:H27) -> 0.0786 | K28: =SUM(K26:K27) -> 0.4839 | L28: =SUM(L26:L27) -> 0.0865 | AH28: X, Horizontal Arm | AI28: m | AK28: 2.124
AH29: Y, Vertical Arm | AI29: m | AK29: 1.0736
AG30: Pasenger | AH30: W, Weight | AI30: kg | AK30: 77.1
AH31: X, Horizontal Arm | AI31: m | AK31: 2.124
G32: Trim Tabs | N32: X' | O32: =K38/H38 -> 6.6113208 | AH32: Y, Vertical Arm | AI32: m | AK32: 1.0736
G33: PORTION | H33: A | I33: X | J33: Y | K33: AX | L33: AY | N33: Y' | O33: =ROUND(L38/H38,4) -> 1.5849 | AG33: Baggage (for Max aft) | AH33: W, Weight | AI33: kg | AK33: 54.42
H34: m^2 | I34: m | J34: m | K34: m^3 | L34: m^3 | AH34: X, Horizontal Arm | AI34: m | AK34: 2.54
G35: Trim Tabs (Wings) | H35: ='ACT 6'!E41 -> 0.0056 | I35: ='ACT 6'!F41 -> 3.1324 | J35: ='ACT 6'!G41 -> 0.7288 | K35: 0.0296 | L35: 0.0085 | AH35: Y, Vertical Arm | AI35: m | AK35: 0.8701
G36: Trim Tabs (Horizontal Tail) | H36: ='ACT 6'!E51 -> 0.0021 | I36: ='ACT 6'!F50 -> 5.8361 | J36: ='ACT 6'!G51 -> 1.1744 | K36: 0.0155 | L36: 0.0026 | AG36: Baggage (for GW CG) | AH36: W, Weight | AI36: kg | AK36: 36.28
G37: Trim Tabs (Vertical Tail) | H37: ='ACT 6'!E60 -> 0.0188 | I37: ='ACT 6'!F60 -> 6.1606 | J37: ='ACT 6'!G60 -> 1.4915 | K37: 0.1301 | L37: 0.0309 | AH37: X, Horizontal Arm | AI37: m | AK37: 2.54
G38: ∑ | H38: =SUM(H35:H37) -> 0.0265 | K38: =SUM(K35:K37) -> 0.1752 | L38: =SUM(L35:L37) -> 0.042 | AH38: Y, Vertical Arm | AI38: m | AK38: 0.8701
AG39: Fuel(Full) | AH39: W, Weight | AI39: kg | AK39: 71.951576
AH40: X, Horizontal Arm | AI40: m | AK40: 2.1782
AH41: Y, Vertical Arm | AI41: m | AK41: 0.7675
G42: TABLE I. BASIC AIRPLANE C,G, POSITION | N42: X' | O42: =J59/H59 -> 2.0244997 | AG42: Oil (Full) | AH42: W, Weight | AI42: kg | AK42: 4.8068507
G43: PORTION | H43: W | I43: X | J43: WX | K43: Y | L43: WY | N43: Y' | O43: =ROUND(L59/H59,4) -> 0.9443 | AH43: X, Horizontal Arm | AI43: m | AK43: 0.816
H44: kg | I44: m | J44: kg-m | K44: m | L44: kg-m | AH44: Y, Vertical Arm | AI44: m | AK44: 0.8478
G45: Wing | H45: ='ACT 5'!E11 -> 95.454545 | I45: 2.2203 | J45: =H45*I45 -> 211.93773 | K45: 0.8124 | L45: =H45*K45 -> 77.547273 | AG45: Fuel in Rear of Tanks | AH45: W, Weight | AI45: kg | AK45: 35.975759
G46: Fuselage, including Canopy | H46: ='ACT 5'!E12 -> 81.818182 | I46: 3.1219 | J46: =H46*I46 -> 255.42818 | K46: 1.111 | L46: =H46*K46 -> 90.9 | AH46: X, Horizontal Arm | AI46: m | AK46: 2.3972
G47: Horizontal Tail including Elevator | H47: ='ACT 5'!E13 -> 15 | I47: 5.5748 | J47: =H47*I47 -> 83.622 | K47: 1.386 | L47: =H47*K47 -> 20.79 | AH47: Y, Vertical Arm | AI47: m | AK47: 0.7676
G48: Vertical Tail including Rudder | H48: ='ACT 5'!E14 -> 14.545455 | I48: 5.7338 | J48: =H48*I48 -> 83.400727 | K48: ='ACT 6'!G58 -> 1.7092 | L48: =H48*K48 -> 24.861091 | AG48: TABLE I. BASIC AIRPLANE C.G. POSITION
G49: Cowling | H49: ='ACT 5'!E15 -> 7.5 | I49: 0.8884 | J49: =H49*I49 -> 6.663 | K49: 0.9331 | L49: =H49*K49 -> 6.99825 | AG49: Wing | AH49: X, Horizontal Arm | AI49: m | AK49: 2.2203
G50: Flaps and Ailerons includiong Controls | H50: ='ACT 5'!E16 -> 14.545455 | I50: 2.6067 | J50: =H50*I50 -> 37.915636 | K50: 0.8819 | L50: =H50*K50 -> 12.827636 | Q50: 2.259 | T50: 2.478 | U50: =T50-R51 -> 2.3972 | AH50: Y, Vertical Arm | AI50: m | AK50: 0.8124
...

Sheet ACT 8
G4: α(@Cl max) | I4: 21.47 | J4: deg.
G6: Max AFT C.G. Position (Taken form Act No. 7) | M6: Gross Weight
G7: X' | H7: 2.06 | I7: m | M7: MTOW | N7: {='ACT 3'!F2:G2} -> 1649.2521 | O7: 0 | P7: lbs
G8: Y' | H8: 0.98 | I8: m | N8: {='ACT 3'!F3:G3} -> 748.08758 | O8: 0 | P8: kg
M10: Wf | N10: {='ACT 3'!F11:G11} -> 158.62607 | O10: 0 | P10: lbs
G11: Gross Weight C.G. Position (Taken from Act No. 7) | N11: {='ACT 3'!F12:G12} -> 71.951518 | O11: 0 | P11: kg
G12: X' | H12: 2.05 | I12: m
G13: Y' | H13: 0.97 | I13: m | M13: Wing Area (S)
M14: S | N14: ='ACT 3'!J4 -> 126.521 | O14: ft
A16: Type of Shock Absorber | B16: η | G16: WL | I16: =N7-0.25*(N10) -> 1609.5956 | J16: lbs | M16: g | N16: 32.174 | O16: ft/s2
A17: Tires | B17: 0.47 | G17: v (max rate of descent) | I17: =4.4*(I16/N14)^(1/4) -> 8.3098124 | J17: fps
A18: Steel Springs | B18: 0.5 | M18: L/W | N18: 3 | O18: normally used forstandard aircraft
A19: Rubber Rings | B19: 0.6 | G19: η ∙ S | I19: =((I17)^2)/(2*N16*(N18))*12 -> 4.292471 | J19: in
A20: Oleo-pneumatic | B20: 0.75 | G20: Load in Nose Wheel | I20: =(N7)*((N20-N21)/N20) -> 195.40892 | J20: lbs | M20: d | N20: 1.689439 | O20: m
G21: Load in Main Wheel (each) | I21: =(N7-I20)/2 -> 726.92161 | J21: lbs | M21: a | N21: 1.4892686 | O21: m
G22: Ss | I22: =(I19-(B17*H31))/(B20) -> 3.8432947 | J22: in
I23: =I22*0.0254 -> 0.097619686 | J23: m
G25: Selected
G26: Static Load | H26: 800 | K26: lb | L26: ← corrected: 800 lb tier; computed main gear load = 726.9 lb/wheel > 700 lb rating
G27: Tire Size | H27: 5.00 – 4 | K27: in
G28: Ply Rating | H28: 4 | K28: -
G29: Tire O. Diameter | H29: 14.2 | K29: in
G30: Flat Tire Radius | H30: 4.1 | K30: in
G31: Max. Tire Deflection | H31: 3 | K31: in
A34: Static Load | B34: Tire Size | C34: Ply Rating | D34: Tire O. Diameter | E34: Flat Tire Radius | F34: Max. Tire Deflection
A35: lb | B35: in. | C35: - | D35: in. | E35: in. | F35: in.
A36: 700 | B36: 5.00 – 4 | C36: 4 | D36: 13.25 | E36: 3.6 | F36: 3.02
A37: 800 | B37: 5.00 – 4 | C37: 4 | D37: 14.2 | E37: 4.1 | F37: 3
A38: 1100 | B38: 6.00 – 6 | C38: 5 | D38: 17.5 | E38: 4.5 | F38: 4.25

Sheet ACT 9
O7: Clean Airplane | U7: Dirty Airplane
F8: Aileron | G8: 0.044 | O8: Part | P8: Description | Q8: CDπ | R8: Aπ | S8: CDπAπ | U8: Part | W8: Description | X8: CDπ | Y8: Aπ | Z8: CDπAπ | AB8: Fuselage | AC8: ΣAπ | AG8: 1.2656
F9: Flaps | G9: 0.0696 | R9: m2 | S9: m2 | X9: — | Y9: m2 | Z9: m2 | AB9: Figure 14.2 | AC9: (Δ(1/e)fuselage) / (Sπfuselage/s) | AG9: 1.68
O10: Wing | P10: NACA 2415 | Q10: 0.008 | R10: 11.754 | S10: =Q10*R10 -> 0.094032 | U10: Wing | W10: NACA 2412 | X10: 0.008 | Y10: 11.754 | Z10: =X10*Y10 -> 0.094032 | AB10: CDπ | AC10: Wing | AD10: 0.004-0.010
AC11: Fuselage | AD11: 0.09-0.20
O12: Fuselage | P12: Small plane, Nose | Q12: 0.12 | R12: 1.2656 | S12: =Q12*R12 -> 0.151872 | U12: Fuselage | W12: Small plane, Nose | X12: 0.12 | Y12: 1.2656 | Z12: =X12*Y12 -> 0.151872 | AC12: Vertical Tail | AD12: 0.006-0.008
P13: Engine | AC13: Horizontal Tail | AD13: 0.006-0.008
F14: Areas | G14: ft2 | H14: m2 | K14: 0.1009 | O14: Vertical Tail | P14: NACA 0012 | Q14: 0.008 | R14: 0.5253 | S14: =Q14*R14 -> 0.0042024 | U14: Vertical Tail | W14: NACA 0012 | X14: 0.008 | Y14: 0.5253 | Z14: =X14*Y14 -> 0.0042024 | AC14: Nose Wheel and Strut | AD14: 0.5-0.8
B15: Aspect Ratio | C15: 6.58 | F15: Wing Gross | G15: ='ACT 3'!J4 -> 126.521 | H15: ='ACT 3'!K4 -> 11.754181 | K15: 0.2112 | AC15: Main Wheel and Strut | AD15: 0.3-0.5
F16: Aileron (total) | G16: ='ACT 3'!W4 -> 8.85647 | H16: ='ACT 3'!X4 -> 0.82279264 | K16: 0.2919 | O16: Horizontal Tail | P16: NACA 0012 | Q16: 0.008 | R16: 1.6761 | S16: =Q16*R16 -> 0.0134088 | U16: Horizontal Tail | W16: NACA 0012 | X16: 0.008 | Y16: 1.6761 | Z16: =X16*Y16 -> 0.0134088 | AC16: Flaps | AD16: 0.02-0.3
F17: Flaps (total) | G17: ='ACT 3'!T15 -> 14.406801 | H17: ='ACT 3'!U15 -> 1.338435 | K17: 0.0253 | AB17: kf | AC17: Correction Factor | AD17: 0.13-0.15
F18: Vertical Tail | G18: =(1/0.092903)*H18 -> 10.832804 | H18: 1.0064 | K18: 0.0035 | P18: Nose wheel and Strut | Q18: 0.69 | R18: 0.1135 | S18: =Q18*R18 -> 0.078315 | W18: Nose wheel and Strut | X18: 0.69 | Y18: 0.1135 | Z18: 0.078
B19: Gross Weight | C19: {='ACT 3'!F3:G3} -> 748.08758 | D19: 0 | F19: Horizontal Tail | G19: =(1/0.092903)*H19 -> 0.86864794 | H19: ='ACT 6'!E52 -> 0.0807 | K19: =SUM(K14:K18) -> 0.6328 | L19: =K19*2 -> 1.2656 | O19: Landing Gear | U19: Landing Gear
C20: {='ACT 3'!F2:G2} -> 1649.2521 | D20: 0 | P20: Main Wheels and Strut | Q20: 0.42 | R20: 0.119 | S20: =Q20*R20 -> 0.04998 | W20: Wheels and Strut | X20: 0.42 | Y20: 0.119 | Z20: 0.05
O22: ΣCDπAπ | S22: =SUM(S10:S21) -> 0.3918102 | U22: Flaps | V22: 60% span, Deflected 30 | X22: 0.022 | Y22: 1.384 | Z22: =X22*Y22 -> 0.030448
O23: Interference (Add 5% to | S23: =S22*0.05 -> 0.01959051
O24: )
O25: Roughness and Protuberances (Add 10% to | S25: =S22*0.1 -> 0.03918102 | U25: ΣCDπAπ | Z25: =SUM(Z10:Z24) -> 0.4219632
O26: )
Q27: ΣCDπAπTotal | S27: =SUM(S22:S26) -> 0.45058173 | U27: Interference (Add 5% to ΣCDπAπ) | Z27: =Z25*0.05 -> 0.02109816
U29: Roughness and Protuberances (Add 10% to ΣCDπAπ) | Z29: =Z25*0.1 -> 0.04219632
O31: Cdo | P31: =S27/H15 -> 0.038333743 | X31: ΣCDπAπTotal | Z31: =SUM(Z25:Z30) -> 0.48525768
P32: =1/(3.14*6.58*0.772) -> 0.06269417 | Q32: cl^2
X35: CDO | Y35: =Z31/H15 -> 0.041283838

Sheet ACT 10
G1: ACT 10
C3: changeable | F3: ① | G3: ② | H3: ③ | I3: ④ | J3: ⑤ | L3: ⑥ | M3: ⑦ | N3: ⑧ | O3: ⑨ | P3: ⑩ | Q3: ⑪ | R3: ⑫ | S3: ⑬
C4: cant touch this | F4: SEA LEVEL | L4: h = 5,000 ft | N4: h = 10,000 ft | P4: h = 15,000 ft | R4: h = 20,000 ft
F5: Vo | G5: CL | H5: CD | I5: TREQo | J5: THPREQDo | L5: V | M5: THPREQD | N5: V | O5: THPREQD | P5: V | Q5: THPREQD | R5: V | S5: THPREQD
F6: mph | G6: — | H6: — | I6: lb | J6: hp | L6: mph | M6: hp | N6: mph | O6: hp | P6: mph | Q6: hp | R6: mph | S6: hp
B7: Given: | C7: Values | F7: =C18 -> 60 | G7: =($C$8*2/((0.002377)*($C$9)*((F7*22)/15)^2)) -> 1.4163152 | H7: =$C$12+($C$13*G7^2) -> 0.16409503 | I7: =$C$8*(H7/G7) -> 191.08323 | J7: =(I7*F7)/375 -> 30.573317 | L7: =F7/SQRT($C$24) -> 64.638241 | M7: =J7/SQRT($C$24) -> 32.936757 | N7: =F7/SQRT($C$25) -> 69.823143 | O7: =J7/SQRT($C$25) -> 35.578751 | P7: =F7/SQRT($C$26) -> 75.643031 | Q7: =J7/SQRT($C$26) -> 38.544306 | R7: =F7/SQRT($C$27) -> 82.204679 | S7: =J7/SQRT($C$27) -> 41.887828
B8: W (lbs) | C8: ='ACT 3'!F2 -> 1649.2521 | F8: =F7+10 -> 70 | G8: =($C$8*2/((0.002377)*($C$9)*((F8*22)/15)^2)) -> 1.0405581 | H8: =$C$12+($C$13*G8^2) -> 0.10621655 | I8: =$C$8*(H8/G8) -> 168.34993 | J8: =(I8*F8)/375 -> 31.42532 | L8: =F8/SQRT($C$24) -> 75.411282 | M8: =J8/SQRT($C$24) -> 33.854623 | N8: =F8/SQRT($C$25) -> 81.460333 | O8: =J8/SQRT($C$25) -> 36.570243 | P8: =F8/SQRT($C$26) -> 88.250202 | Q8: =J8/SQRT($C$26) -> 39.61844 | R8: =F8/SQRT($C$27) -> 95.905459 | S8: =J8/SQRT($C$27) -> 43.055139
B9: S (ft^2) | C9: ='ACT 3'!J4 -> 126.521 | F9: =F8+10 -> 80 | G9: =($C$8*2/((0.002377)*($C$9)*((F9*22)/15)^2)) -> 0.79667729 | H9: =$C$12+($C$13*G9^2) -> 0.0781254 | I9: =$C$8*(H9/G9) -> 161.73234 | J9: =(I9*F9)/375 -> 34.5029 | L9: =F9/SQRT($C$24) -> 86.184322 | M9: =J9/SQRT($C$24) -> 37.170113 | N9: =F9/SQRT($C$25) -> 93.097523 | O9: =J9/SQRT($C$25) -> 40.151681 | P9: =F9/SQRT($C$26) -> 100.85737 | Q9: =J9/SQRT($C$26) -> 43.498398 | R9: =F9/SQRT($C$27) -> 109.60624 | S9: =J9/SQRT($C$27) -> 47.271663
B10: CL MAX | C10: 1.54 | F10: =F9+10 -> 90 | G10: =($C$8*2/((0.002377)*($C$9)*((F10*22)/15)^2)) -> 0.62947341 | H10: =$C$12+($C$13*G10^2) -> 0.063175478 | I10: =$C$8*(H10/G10) -> 165.52295 | J10: =(I10*F10)/375 -> 39.725507 | L10: =F10/SQRT($C$24) -> 96.957362 | M10: =J10/SQRT($C$24) -> 42.796448 | N10: =F10/SQRT($C$25) -> 104.73471 | O10: =J10/SQRT($C$25) -> 46.229329 | P10: =F10/SQRT($C$26) -> 113.46455 | Q10: =J10/SQRT($C$26) -> 50.082629 | R10: =F10/SQRT($C$27) -> 123.30702 | S10: =J10/SQRT($C$27) -> 54.427042
B11: CD (clean) | F11: =F10+10 -> 100 | G11: =($C$8*2/((0.002377)*($C$9)*((F11*22)/15)^2)) -> 0.50987346 | H11: =$C$12+($C$13*G11^2) -> 0.054632405 | I11: =$C$8*(H11/G11) -> 176.71563 | J11: =(I11*F11)/375 -> 47.124169 | L11: =F11/SQRT($C$24) -> 107.7304 | M11: =J11/SQRT($C$24) -> 50.767057 | N11: =F11/SQRT($C$25) -> 116.3719 | O11: =J11/SQRT($C$25) -> 54.839293 | P11: =F11/SQRT($C$26) -> 126.07172 | Q11: =J11/SQRT($C$26) -> 59.410249 | R11: =F11/SQRT($C$27) -> 137.0078 | S11: =J11/SQRT($C$27) -> 64.563786
B12: Cdo | C12: ='ACT 9'!P31 -> 0.038333743 | F12: =F11+10 -> 110 | G12: =($C$8*2/((0.002377)*($C$9)*((F12*22)/15)^2)) -> 0.42138303 | H12: =$C$12+($C$13*G12^2) -> 0.049465949 | I12: =$C$8*(H12/G12) -> 193.60491 | J12: =(I12*F12)/375 -> 56.790773 | L12: =F12/SQRT($C$24) -> 118.50344 | M12: =J12/SQRT($C$24) -> 61.180928 | N12: =F12/SQRT($C$25) -> 128.00909 | O12: =J12/SQRT($C$25) -> 66.088504 | P12: =F12/SQRT($C$26) -> 138.67889 | Q12: =J12/SQRT($C$26) -> 71.597103 | R12: =F12/SQRT($C$27) -> 150.70858 | S12: =J12/SQRT($C$27) -> 77.807787
B13: Cdi | C13: ='ACT 9'!P32 -> 0.06269417 | D13: CL^2 | F13: =F12+10 -> 120 | G13: =($C$8*2/((0.002377)*($C$9)*((F13*22)/15)^2)) -> 0.35407879 | H13: =$C$12+($C$13*G13^2) -> 0.046193823 | I13: =$C$8*(H13/G13) -> 215.16471 | J13: =(I13*F13)/375 -> 68.852708 | L13: =F13/SQRT($C$24) -> 129.27648 | M13: =J13/SQRT($C$24) -> 74.175299 | N13: =F13/SQRT($C$25) -> 139.64629 | O13: =J13/SQRT($C$25) -> 80.125207 | P13: =F13/SQRT($C$26) -> 151.28606 | Q13: =J13/SQRT($C$26) -> 86.803791 | R13: =F13/SQRT($C$27) -> 164.40936 | S13: =J13/SQRT($C$27) -> 94.333579
F14: =F13+10 -> 130 | G14: =($C$8*2/((0.002377)*($C$9)*((F14*22)/15)^2)) -> 0.30170027 | H14: =$C$12+($C$13*G14^2) -> 0.044040357 | I14: =$C$8*(H14/G14) -> 240.74772 | J14: =(I14*F14)/375 -> 83.459211 | L14: =F14/SQRT($C$24) -> 140.04952 | M14: =J14/SQRT($C$24) -> 89.910943 | N14: =F14/SQRT($C$25) -> 151.28348 | O14: =J14/SQRT($C$25) -> 97.123073 | P14: =F14/SQRT($C$26) -> 163.89323 | Q14: =J14/SQRT($C$26) -> 105.21846 | R14: =F14/SQRT($C$27) -> 178.11014 | S14: =J14/SQRT($C$27) -> 114.34563
F15: =F14+10 -> 140 | G15: =($C$8*2/((0.002377)*($C$9)*((F15*22)/15)^2)) -> 0.26013952 | H15: =$C$12+($C$13*G15^2) -> 0.042576418 | I15: =$C$8*(H15/G15) -> 269.92918 | J15: =(I15*F15)/375 -> 100.77356 | L15: =F15/SQRT($C$24) -> 150.82256 | M15: =J15/SQRT($C$24) -> 108.56376 | N15: =F15/SQRT($C$25) -> 162.92067 | O15: =J15/SQRT($C$25) -> 117.27211 | P15: =F15/SQRT($C$26) -> 176.5004 | Q15: =J15/SQRT($C$26) -> 127.04696 | R15: =F15/SQRT($C$27) -> 191.81092 | S15: =J15/SQRT($C$27) -> 138.06764
B16: VMIN (mph) | C16: =SQRT((C8/C9)*(2/0.002377)*(1/C10))*(15/22) -> 57.540131 | D16: =SQRT((C8/C9)*(2/0.002377)*(1/C10)) -> 84.392192 | F16: =F15+10 -> 150 | G16: =($C$8*2/((0.002377)*($C$9)*((F16*22)/15)^2)) -> 0.22661043 | H16: =$C$12+($C$13*G16^2) -> 0.041553232 | I16: =$C$8*(H16/G16) -> 302.42102 | J16: =(I16*F16)/375 -> 120.96841 | L16: =F16/SQRT($C$24) -> 161.5956 | M16: =J16/SQRT($C$24) -> 130.31975 | N16: =F16/SQRT($C$25) -> 174.55786 | O16: =J16/SQRT($C$25) -> 140.77324 | P16: =F16/SQRT($C$26) -> 189.10758 | Q16: =J16/SQRT($C$26) -> 152.50695 | R16: =F16/SQRT($C$27) -> 205.5117 | S16: =J16/SQRT($C$27) -> 165.73615
B17: Therefore: Assumptions start at | F17: =F16+10 -> 160 | G17: =($C$8*2/((0.002377)*($C$9)*((F17*22)/15)^2)) -> 0.19916932 | H17: =$C$12+($C$13*G17^2) -> 0.040820721 | I17: =$C$8*(H17/G17) -> 338.02225 | J17: =(I17*F17)/375 -> 144.22283 | L17: =F17/SQRT($C$24) -> 172.36864 | M17: =J17/SQRT($C$24) -> 155.37183 | N17: =F17/SQRT($C$25) -> 186.19505 | O17: =J17/SQRT($C$25) -> 167.83485 | P17: =F17/SQRT($C$26) -> 201.71475 | Q17: =J17/SQRT($C$26) -> 181.82419 | R17: =F17/SQRT($C$27) -> 219.21248 | S17: =J17/SQRT($C$27) -> 197.59652
B18: Vo (mph) | C18: =ROUND(C16, -1) -> 60 | F18: =F17+10 -> 170 | G18: =($C$8*2/((0.002377)*($C$9)*((F18*22)/15)^2)) -> 0.1764268 | H18: =$C$12+($C$13*G18^2) -> 0.040285187 | I18: =$C$8*(H18/G18) -> 376.58922 | J18: =(I18*F18)/375 -> 170.72044 | L18: =F18/SQRT($C$24) -> 183.14168 | M18: =J18/SQRT($C$24) -> 183.91782 | N18: =F18/SQRT($C$25) -> 197.83224 | O18: =J18/SQRT($C$25) -> 198.67063 | P18: =F18/SQRT($C$26) -> 214.32192 | Q18: =J18/SQRT($C$26) -> 215.2302 | R18: =F18/SQRT($C$27) -> 232.91326 | S18: =J18/SQRT($C$27) -> 233.90032
F19: =F18+10 -> 180 | G19: =($C$8*2/((0.002377)*($C$9)*((F19*22)/15)^2)) -> 0.15736835 | H19: =$C$12+($C$13*G19^2) -> 0.039886351 | I19: =$C$8*(H19/G19) -> 418.01702 | J19: =(I19*F19)/375 -> 200.64817 | L19: =F19/SQRT($C$24) -> 193.91472 | M19: =J19/SQRT($C$24) -> 216.15908 | N19: =F19/SQRT($C$25) -> 209.46943 | O19: =J19/SQRT($C$25) -> 233.4981 | P19: =F19/SQRT($C$26) -> 226.92909 | Q19: =J19/SQRT($C$26) -> 252.96059 | R19: =F19/SQRT($C$27) -> 246.61404 | S19: =J19/SQRT($C$27) -> 274.90364
F20: =F19+10 -> 190 | G20: =($C$8*2/((0.002377)*($C$9)*((F20*22)/15)^2)) -> 0.14123919 | H20: =$C$12+($C$13*G20^2) -> 0.039584398 | I20: =$C$8*(H20/G20) -> 462.22762 | J20: =(I20*F20)/375 -> 234.19533 | L20: =F20/SQRT($C$24) -> 204.68776 | M20: =J20/SQRT($C$24) -> 252.29957 | N20: =F20/SQRT($C$25) -> 221.10662 | O20: =J20/SQRT($C$25) -> 272.53756 | P20: =F20/SQRT($C$26) -> 239.53626 | Q20: =J20/SQRT($C$26) -> 295.25407 | R20: =F20/SQRT($C$27) -> 260.31482 | S20: =J20/SQRT($C$27) -> 320.86586
B21: ALTITUDE, h | C21: DENSITY RATIO, σ | F21: =F20+10 -> 200 | G21: =($C$8*2/((0.002377)*($C$9)*((F21*22)/15)^2)) -> 0.12746837 | H21: =$C$12+($C$13*G21^2) -> 0.039352409 | I21: =$C$8*(H21/G21) -> 509.16197 | J21: =(I21*F21)/375 -> 271.55305 | L21: =F21/SQRT($C$24) -> 215.4608 | M21: =J21/SQRT($C$24) -> 292.5452 | N21: =F21/SQRT($C$25) -> 232.74381 | O21: =J21/SQRT($C$25) -> 316.01146 | P21: =F21/SQRT($C$26) -> 252.14344 | Q21: =J21/SQRT($C$26) -> 342.3516 | R21: =F21/SQRT($C$27) -> 274.0156 | S21: =J21/SQRT($C$27) -> 372.04886
B22: ft | C22: —
B23: SEA LEVEL | C23: =(1+((-0.003566)*(0)/(519)))^4.26 -> 1
B24: 5000 | C24: =(1+((-0.003566)*(B24)/(519)))^4.26 -> 0.86163521
B25: 10000 | C25: =(1+((-0.003566)*(B25)/(519)))^4.26 -> 0.73842045
B26: 15000 | C26: =(1+((-0.003566)*(B26)/(519)))^4.26 -> 0.62916515
B27: 20000 | C27: =(1+((-0.003566)*(B27)/(519)))^4.26 -> 0.53273279

Sheet ACT 11
G1: ACT 11
C3: changeable | F3: ① | G3: ② | H3: ③ | I3: ④ | J3: ⑤ | M3: ① | N3: ② | O3: ③ | P3: ④ | Q3: ⑤ | R3: ⑥ | S3: ⑦ | T3: ⑧ | U3: ⑨ | V3: ⑩ | X3: ⑪ | Y3: ⑫ | Z3: ⑬ | AA3: ⑭ | AB3: ⑮ | AC3: ⑯ | AD3: ⑰ | AE3: ⑱
C4: cant touch this | F4: SEA LEVEL | M4: SEA LEVEL | X4: h = 5,000 ft | Y4: SEA LEVEL | Z4: h = 5,000 ft
F5: Vo | G5: CL | H5: CD | I5: TREQo | J5: THPREQDo | M5: V | N5: % Design | O5: % Design | P5: N | Q5: BHP | R5: V/ND | S5: % Design | T5: % Design | V5: THPAV | X5: N | Y5: BHB at Reduced N | Z5: BHP | AA5: V/ND | AB5: % Design | AC5: % Design | AE5: THPAV
F6: mph | G6: — | H6: — | I6: lb | J6: hp | N6: V | O6: N | S6: V/ND | AB6: V/ND
B7: Given: | C7: Values | F7: =C18 -> 60 | G7: =($C$8*2/((0.002377)*($C$9)*((F7*22)/15)^2)) -> 1.4163152 | H7: =$C$12+($C$13*G7^2) -> 0.16409503 | I7: =$C$8*(H7/G7) -> 191.08323 | J7: =(I7*F7)/375 -> 30.573317 | M7: mph | N7: % | O7: % | P7: rpm | Q7: hp | R7: - | S7: % | T7: % | U7: % | V7: hp | X7: rpm | Y7: hp | Z7: hp | AA7: - | AB7: % | AC7: % | AD7: % | AE7: hp
B8: W (lbs) | C8: ='ACT 3'!F2 -> 1649.2521 | F8: =F7+10 -> 70 | G8: =($C$8*2/((0.002377)*($C$9)*((F8*22)/15)^2)) -> 1.0405581 | H8: =$C$12+($C$13*G8^2) -> 0.10621655 | I8: =$C$8*(H8/G8) -> 168.34993 | J8: =(I8*F8)/375 -> 31.42532 | M8: 60 | N8: =(M8/$P$34)*100 -> 43.443841 | O8: 86.12 | P8: =(O8/100)*($C$34) -> 2196.06 | Q8: =(O8/100)*($C$32) -> 107.65 | R8: =(M8*88)/(P8*$P$37) -> 0.3652269 | S8: =(R8/$C$37)*100 -> 50.445705 | T8: 60.53 | U8: =(T8)*($C$31) -> 47.2134 | V8: =Q8*(U8/100) -> 50.825225 | X8: =P8*0.995 -> 2185.0797 | Y8: =(($C$32)*X8)/($C$34) -> 107.11175 | Z8: =Y8*0.82 -> 87.831635 | AA8: =(M8*88)/(X8*$P$37) -> 0.36706221 | AB8: =(AA8/$C$37)*100 -> 50.699201 | AC8: 60.89 | AD8: =AC8*$C$31 -> 47.4942 | AE8: =(Z8*AD8)/100 -> 41.714932
B9: S (ft^2) | C9: ='ACT 3'!J4 -> 126.521 | F9: =F8+10 -> 80 | G9: =($C$8*2/((0.002377)*($C$9)*((F9*22)/15)^2)) -> 0.79667729 | H9: =$C$12+($C$13*G9^2) -> 0.0781254 | I9: =$C$8*(H9/G9) -> 161.73234 | J9: =(I9*F9)/375 -> 34.5029 | M9: 70 | N9: =(M9/$P$34)*100 -> 50.684481 | O9: 86.89 | P9: =(O9/100)*($C$34) -> 2215.695 | Q9: =(O9/100)*($C$32) -> 108.6125 | R9: =(M9*88)/(P9*$P$37) -> 0.42232206 | S9: =(R9/$C$37)*100 -> 58.331777 | T9: 68.42 | U9: =(T9)*($C$31) -> 53.3676 | V9: =Q9*(U9/100) -> 57.963885 | X9: =P9*0.995 -> 2204.6165 | Y9: =(($C$32)*X9)/($C$34) -> 108.06944 | Z9: =Y9*0.82 -> 88.616939 | AA9: =(M9*88)/(X9*$P$37) -> 0.42444429 | AB9: =(AA9/$C$37)*100 -> 58.624901 | AC9: 69.12 | AD9: =AC9*$C$31 -> 53.9136 | AE9: =(Z9*AD9)/100 -> 47.776582
B10: CL MAX | C10: 1.54 | F10: =F9+10 -> 90 | G10: =($C$8*2/((0.002377)*($C$9)*((F10*22)/15)^2)) -> 0.62947341 | H10: =$C$12+($C$13*G10^2) -> 0.063175478 | I10: =$C$8*(H10/G10) -> 165.52295 | J10: =(I10*F10)/375 -> 39.725507 | M10: 80 | N10: =(M10/$P$34)*100 -> 57.925121 | O10: 87.3 | P10: =(O10/100)*($C$34) -> 2226.15 | Q10: =(O10/100)*($C$32) -> 109.125 | R10: =(M10*88)/(P10*$P$37) -> 0.48038703 | S10: =(R10/$C$37)*100 -> 66.3518 | T10: 77.12 | U10: =(T10)*($C$31) -> 60.1536 | V10: =Q10*(U10/100) -> 65.642616 | X10: =P10*0.995 -> 2215.0193 | Y10: =(($C$32)*X10)/($C$34) -> 108.57938 | Z10: =Y10*0.82 -> 89.035088 | AA10: =(M10*88)/(X10*$P$37) -> 0.48280103 | AB10: =(AA10/$C$37)*100 -> 66.685226 | AC10: 77.89 | AD10: =AC10*$C$31 -> 60.7542 | AE10: =(Z10*AD10)/100 -> 54.092555
B11: CD (clean) | F11: =F10+10 -> 100 | G11: =($C$8*2/((0.002377)*($C$9)*((F11*22)/15)^2)) -> 0.50987346 | H11: =$C$12+($C$13*G11^2) -> 0.054632405 | I11: =$C$8*(H11/G11) -> 176.71563 | J11: =(I11*F11)/375 -> 47.124169 | M11: 90 | N11: =(M11/$P$34)*100 -> 65.165761 | O11: 88.1 | P11: =(O11/100)*($C$34) -> 2246.55 | Q11: =(O11/100)*($C$32) -> 110.125 | R11: =(M11*88)/(P11*$P$37) -> 0.53552793 | S11: =(R11/$C$37)*100 -> 73.967947 | T11: 84.43 | U11: =(T11)*($C$31) -> 65.8554 | V11: =Q11*(U11/100) -> 72.523259 | X11: =P11*0.995 -> 2235.3172 | Y11: =(($C$32)*X11)/($C$34) -> 109.57437 | Z11: =Y11*0.82 -> 89.850987 | AA11: =(M11*88)/(X11*$P$37) -> 0.53821903 | AB11: =(AA11/$C$37)*100 -> 74.339645 | AC11: 84.86 | AD11: =AC11*$C$31 -> 66.1908 | AE11: =(Z11*AD11)/100 -> 59.473087
B12: Cdo | C12: ='ACT 9'!P31 -> 0.038333743 | F12: =F11+10 -> 110 | G12: =($C$8*2/((0.002377)*($C$9)*((F12*22)/15)^2)) -> 0.42138303 | H12: =$C$12+($C$13*G12^2) -> 0.049465949 | I12: =$C$8*(H12/G12) -> 193.60491 | J12: =(I12*F12)/375 -> 56.790773 | M12: 100 | N12: =(M12/$P$34)*100 -> 72.406401 | O12: 90.1 | P12: =(O12/100)*($C$34) -> 2297.55 | Q12: =(O12/100)*($C$32) -> 112.625 | R12: =(M12*88)/(P12*$P$37) -> 0.5818228 | S12: =(R12/$C$37)*100 -> 80.362266 | T12: 91.02 | U12: =(T12)*($C$31) -> 70.9956 | V12: =Q12*(U12/100) -> 79.958794 | X12: =P12*0.995 -> 2286.0622 | Y12: =(($C$32)*X12)/($C$34) -> 112.06187 | Z12: =Y12*0.82 -> 91.890737 | AA12: =(M12*88)/(X12*$P$37) -> 0.58474654 | AB12: =(AA12/$C$37)*100 -> 80.766096 | AC12: 90.23 | AD12: =AC12*$C$31 -> 70.3794 | AE12: =(Z12*AD12)/100 -> 64.67215
B13: Cdi | C13: ='ACT 9'!P32 -> 0.06269417 | D13: CL^2 | F13: =F12+10 -> 120 | G13: =($C$8*2/((0.002377)*($C$9)*((F13*22)/15)^2)) -> 0.35407879 | H13: =$C$12+($C$13*G13^2) -> 0.046193823 | I13: =$C$8*(H13/G13) -> 215.16471 | J13: =(I13*F13)/375 -> 68.852708 | M13: 110 | N13: =(M13/$P$34)*100 -> 79.647041 | O13: 93.12 | P13: =(O13/100)*($C$34) -> 2374.56 | Q13: =(O13/100)*($C$32) -> 116.4 | R13: =(M13*88)/(P13*$P$37) -> 0.6192489 | S13: =(R13/$C$37)*100 -> 85.531617 | T13: 94.98 | U13: =(T13)*($C$31) -> 74.0844 | V13: =Q13*(U13/100) -> 86.234242 | X13: =P13*0.995 -> 2362.6872 | Y13: =(($C$32)*X13)/($C$34) -> 115.818 | Z13: =Y13*0.82 -> 94.97076 | AA13: =(M13*88)/(X13*$P$37) -> 0.62236071 | AB13: =(AA13/$C$37)*100 -> 85.961424 | AC13: 94.76 | AD13: =AC13*$C$31 -> 73.9128 | AE13: =(Z13*AD13)/100 -> 70.195548
F14: =F13+10 -> 130 | G14: =($C$8*2/((0.002377)*($C$9)*((F14*22)/15)^2)) -> 0.30170027 | H14: =$C$12+($C$13*G14^2) -> 0.044040357 | I14: =$C$8*(H14/G14) -> 240.74772 | J14: =(I14*F14)/375 -> 83.459211 | M14: 120 | N14: =(M14/$P$34)*100 -> 86.887682 | O14: 94.94 | P14: =(O14/100)*($C$34) -> 2420.97 | Q14: =(O14/100)*($C$32) -> 118.675 | R14: =(M14*88)/(P14*$P$37) -> 0.66259407 | S14: =(R14/$C$37)*100 -> 91.518519 | T14: 97.91 | U14: =(T14)*($C$31) -> 76.3698 | V14: =Q14*(U14/100) -> 90.63186 | X14: =P14*0.995 -> 2408.8652 | Y14: =(($C$32)*X14)/($C$34) -> 118.08163 | Z14: =Y14*0.82 -> 96.826932 | AA14: =(M14*88)/(X14*$P$37) -> 0.66592369 | AB14: =(AA14/$C$37)*100 -> 91.978411 | AC14: 98.12 | AD14: =AC14*$C$31 -> 76.5336 | AE14: =(Z14*AD14)/100 -> 74.105137
F15: =F14+10 -> 140 | G15: =($C$8*2/((0.002377)*($C$9)*((F15*22)/15)^2)) -> 0.26013952 | H15: =$C$12+($C$13*G15^2) -> 0.042576418 | I15: =$C$8*(H15/G15) -> 269.92918 | J15: =(I15*F15)/375 -> 100.77356 | M15: 130 | N15: =(M15/$P$34)*100 -> 94.128322 | O15: 97.31 | P15: =(O15/100)*($C$34) -> 2481.405 | Q15: =(O15/100)*($C$32) -> 121.6375 | R15: =(M15*88)/(P15*$P$37) -> 0.70032787 | S15: =(R15/$C$37)*100 -> 96.730369 | T15: 99.57 | U15: =(T15)*($C$31) -> 77.6646 | V15: =Q15*(U15/100) -> 94.469278 | X15: =P15*0.995 -> 2468.998 | Y15: =(($C$32)*X15)/($C$34) -> 121.02931 | Z15: =Y15*0.82 -> 99.244036 | AA15: =(M15*88)/(X15*$P$37) -> 0.7038471 | AB15: =(AA15/$C$37)*100 -> 97.216451 | AC15: 99.94 | AD15: =AC15*$C$31 -> 77.9532 | AE15: =(Z15*AD15)/100 -> 77.363902
B16: VMIN (mph) | C16: =SQRT((C8/C9)*(2/0.002377)*(1/C10))*(15/22) -> 57.540131 | D16: =SQRT((C8/C9)*(2/0.002377)*(1/C10)) -> 84.392192 | F16: =F15+10 -> 150 | G16: =($C$8*2/((0.002377)*($C$9)*((F16*22)/15)^2)) -> 0.22661043 | H16: =$C$12+($C$13*G16^2) -> 0.041553232 | I16: =$C$8*(H16/G16) -> 302.42102 | J16: =(I16*F16)/375 -> 120.96841 | M16: 140 | N16: =(M16/$P$34)*100 -> 101.36896 | O16: 100.21 | P16: =(O16/100)*($C$34) -> 2555.355 | Q16: =(O16/100)*($C$32) -> 125.2625 | R16: =(M16*88)/(P16*$P$37) -> 0.7323733 | S16: =(R16/$C$37)*100 -> 101.15653 | T16: 99.54 | U16: =(T16)*($C$31) -> 77.6412 | V16: =Q16*(U16/100) -> 97.255308 | X16: =P16*0.995 -> 2542.5782 | Y16: =(($C$32)*X16)/($C$34) -> 124.63619 | Z16: =Y16*0.82 -> 102.20167 | AA16: =(M16*88)/(X16*$P$37) -> 0.73605357 | AB16: =(AA16/$C$37)*100 -> 101.66486 | AC16: 99.98 | AD16: =AC16*$C$31 -> 77.9844 | AE16: =(Z16*AD16)/100 -> 79.701362
B17: Therefore: Assumptions start at | F17: =F16+10 -> 160 | G17: =($C$8*2/((0.002377)*($C$9)*((F17*22)/15)^2)) -> 0.19916932 | H17: =$C$12+($C$13*G17^2) -> 0.040820721 | I17: =$C$8*(H17/G17) -> 338.02225 | J17: =(I17*F17)/375 -> 144.22283 | M17: 150 | N17: =(M17/$P$34)*100 -> 108.6096 | O17: 103.87 | P17: =(O17/100)*($C$34) -> 2648.685 | Q17: =(O17/100)*($C$32) -> 129.8375 | R17: =(M17*88)/(P17*$P$37) -> 0.75703622 | S17: =(R17/$C$37)*100 -> 104.56301 | T17: 98.1 | U17: =(T17)*($C$31) -> 76.518 | V17: =Q17*(U17/100) -> 99.349058 | X17: =P17*0.995 -> 2635.4416 | Y17: =(($C$32)*X17)/($C$34) -> 129.18831 | Z17: =Y17*0.82 -> 105.93442 | AA17: =(M17*88)/(X17*$P$37) -> 0.76084042 | AB17: =(AA17/$C$37)*100 -> 105.08846 | AC17: 98.65 | AD17: =AC17*$C$31 -> 76.947 | AE17: =(Z17*AD17)/100 -> 81.513355
B18: Vo (mph) | C18: =ROUND(C16, -1) -> 60 | F18: =F17+10 -> 170 | G18: =($C$8*2/((0.002377)*($C$9)*((F18*22)/15)^2)) -> 0.1764268 | H18: =$C$12+($C$13*G18^2) -> 0.040285187 | I18: =$C$8*(H18/G18) -> 376.58922 | J18: =(I18*F18)/375 -> 170.72044 | M18: 160 | N18: =(M18/$P$34)*100 -> 115.85024 | O18: 106.83 | P18: =(O18/100)*($C$34) -> 2724.165 | Q18: =(O18/100)*($C$32) -> 133.5375 | R18: =(M18*88)/(P18*$P$37) -> 0.78513129 | S18: =(R18/$C$37)*100 -> 108.44355 | T18: 97.31 | U18: =(T18)*($C$31) -> 75.9018 | V18: =Q18*(U18/100) -> 101.35737 | X18: =P18*0.995 -> 2710.5442 | Y18: =(($C$32)*X18)/($C$34) -> 132.86981 | Z18: =Y18*0.82 -> 108.95325 | AA18: =(M18*88)/(X18*$P$37) -> 0.78907667 | AB18: =(AA18/$C$37)*100 -> 108.98849 | AC18: 97.15 | AD18: =AC18*$C$31 -> 75.777 | AE18: =(Z18*AD18)/100 -> 82.561501
